Workbook

Sheet Feed Ingredients
A1: FEED INGREDIENT DATABASE
A2: Cloudskraal Boerdery — Dohne Merino Feed Calculator
A4: Ingredient | B4: Category | C4: ME (MJ/kg DM) | D4: CP (%DM) | E4: NDF (%DM) | F4: Ca (%DM) | G4: P (%DM) | H4: Cost (R/kg as-fed) | I4: DM (%)
A5: Rye grain (own) | B5: Energy – Farm | C5: 12.5 | D5: 11 | E5: 18 | F5: 0.06 | G5: 0.35 | H5: 3.5 | I5: 88
A6: Barley grain (own) | B6: Energy – Farm | C6: 12.8 | D6: 11.5 | E6: 20 | F6: 0.05 | G6: 0.35 | H6: 3.2 | I6: 88
A7: Wheat grain (own) | B7: Energy – Farm | C7: 13.2 | D7: 12.5 | E7: 14 | F7: 0.05 | G7: 0.4 | H7: 4 | I7: 88
A8: Lupins (own) | B8: Protein – Farm | C8: 12 | D8: 32 | E8: 25 | F8: 0.25 | G8: 0.4 | H8: 5.5 | I8: 89
A9: Lucerne hay (own) | B9: Roughage – Farm | C9: 8.5 | D9: 18 | E9: 42 | F9: 1.4 | G9: 0.25 | H9: 2.8 | I9: 90
A10: Maize meal | B10: Energy – Bought | C10: 13.8 | D10: 9 | E10: 11 | F10: 0.03 | G10: 0.28 | H10: 4.8 | I10: 87
A11: Maize hominy chop | B11: Energy – Bought | C11: 12 | D11: 11 | E11: 32 | F11: 0.05 | G11: 0.8 | H11: 3.6 | I11: 88
A12: Molasses meal | B12: Energy – Bought | C12: 10.5 | D12: 5 | E12: 15 | F12: 0.9 | G12: 0.1 | H12: 2.5 | I12: 75
A13: Cottonseed oilcake | B13: Protein – Bought | C13: 11.5 | D13: 41 | E13: 30 | F13: 0.2 | G13: 1.1 | H13: 6.5 | I13: 90
A14: Sunflower oilcake | B14: Protein – Bought | C14: 10 | D14: 34 | E14: 35 | F14: 0.35 | G14: 1 | H14: 5.8 | I14: 90
A15: Soybean oilcake | B15: Protein – Bought | C15: 13 | D15: 46 | E15: 14 | F15: 0.3 | G15: 0.65 | H15: 9.5 | I15: 89
A16: Fish meal | B16: Protein – Bought | C16: 12 | D16: 63 | E16: 5 | F16: 5 | G16: 2.8 | H16: 18 | I16: 92
... A25: Wheat straw | B25: Roughage – Farm | C25: 5.5 | D25: 3.5 | E25: 78 | F25: 0.2 | G25: 0.06 | H25: 1 | I25: 90
A27: Notes:
A28: * Blue cost values are editable. ME = Metabolisable Energy. CP = Crude Protein (% of DM). NDF = Neutral Detergent Fibre.
A29: * Urea CP equiv = N×6.25 (287%). Max 1% of total diet weight. Pasture costs = R0 (own land, opportunity cost excluded).

Sheet Nutrient Requirements
A1: DOHNE MERINO NUTRIENT REQUIREMENTS BY PHASE
A2: Based on NRC (2007) for 60 kg mature ewe (~132 lb). All values converted to metric. Total diet = grazing + supplement.
A4: Assumed mature ewe weight: | B4: 60 | C4: kg (adjust for your flock)
A6: Phase | B6: Production Stage | C6: DM Intake (kg/d) | D6: ME Required (MJ/d) | E6: CP Required (g/d) | F6: CP (% of DM) | G6: TDN (% of DM) | H6: Ca (g/d) | I6: P (g/d) | J6: Ca:P Ratio | K6: Vit A (IU/d) | L6: Vit E (IU/d)
A7: Maintenance | B7: Dry, non-pregnant | C7: 1.09 | D7: 7.2 | E7: 104 | F7: 9.5 | G7: 54.2 | H7: 2.3 | I7: 2.3 | J7: 1.0:1 | K7: 2820 | L7: 16
A8: Flushing | B8: Pre-breeding + first 3 wks | C8: 1.68 | D8: 12.2 | E8: 154 | F8: 9.2 | G8: 59.5 | H8: 5.4 | I8: 2.7 | J8: 2.0:1 | K8: 2820 | L8: 26
A9: Early Pregnancy | B9: First 15 weeks gestation | C9: 1.32 | D9: 8.9 | E9: 122 | F9: 9.3 | G9: 55.2 | H9: 3.2 | I9: 2.3 | J9: 1.4:1 | K9: 2820 | L9: 20
A10: Late Preg (Singles) | B10: Last 4 wks, 130-150% lambing | C10: 1.68 | D10: 12.2 | E10: 181 | F10: 10.8 | G10: 59.5 | H10: 5.9 | I10: 5 | J10: 1.2:1 | K10: 5100 | L10: 26
A11: Late Preg (Twins) | B11: Last 4 wks, 180-225% lambing | C11: 1.81 | D11: 14.4 | E11: 204 | F11: 11.2 | G11: 65 | H11: 6.8 | I11: 3.6 | J11: 1.9:1 | K11: 5100 | L11: 27
A12: Early Lact (Singles) | B12: First 6-8 wks, suckling singles | C12: 2.31 | D12: 18.3 | E12: 318 | F12: 13.7 | G12: 64.7 | H12: 9.1 | I12: 6.4 | J12: 1.4:1 | K12: 5100 | L12: 34
A13: Early Lact (Twins) | B13: First 6-8 wks, suckling twins | C13: 2.59 | D13: 20.5 | E13: 404 | F13: 15.6 | G13: 64.9 | H13: 10.4 | I13: 7.7 | J13: 1.4:1 | K13: 6000 | L13: 39
A14: Peak Lact (Singles) | B14: Weeks 3-4 peak milk, singles | C14: 2.31 | D14: 18.3 | E14: 318 | F14: 13.7 | G14: 64.7 | H14: 9.1 | I14: 6.4 | J14: 1.4:1 | K14: 5100 | L14: 34
A15: Peak Lact (Twins) | B15: Weeks 3-4 peak milk, twins | C15: 2.59 | D15: 20.5 | E15: 404 | F15: 15.6 | G15: 64.9 | H15: 10.4 | I15: 7.7 | J15: 1.4:1 | K15: 6000 | L15: 39
A16: Late Lact (Singles) | B16: Weeks 8-12, singles | C16: 1.68 | D16: 12.2 | E16: 181 | F16: 10.8 | G16: 59.5 | H16: 5.9 | I16: 5 | J16: 1.2:1 | K16: 5100 | L16: 26
A17: Late Lact (Twins) | B17: Weeks 8-12, twins | C17: 2.31 | D17: 18.3 | E17: 318 | F17: 13.7 | G17: 64.7 | H17: 9.1 | I17: 6.4 | J17: 1.4:1 | K17: 5100 | L17: 34
A18: Growing Lamb | B18: Weaner, 30kg, gaining 200g/d | C18: 1.18 | D18: 10.9 | E18: 177 | F18: 15 | G18: 65 | H18: 5.9 | I18: 2.7 | J18: 2.2:1 | K18: 1410 | L18: 20
... A20: Ram (breeding) | B20: Mature ram, 90kg | C20: 2.04 | D20: 14.4 | E20: 190 | F20: 9.3 | G20: 54.5 | H20: 5.4 | I20: 5.4 | J20: 1.0:1 | K20: 3760 | L20: 20
A22: ESTIMATED GRAZING CONTRIBUTION (what the veld/pasture provides before supplementation)
A23: Pasture Type | B23: Season | C23: Est. DM Intake (kg/d) | D23: ME from grazing (MJ/d) | E23: CP from grazing (g/d) | F23: Ca from grazing (g/d) | G23: P from grazing (g/d)
A24: Rye pasture (winter, good) | B24: May–Aug | C24: 1.2 | D24: 12.6 | E24: 192 | F24: 5.4 | G24: 4.2
A25: Rye pasture (spring, mature) | B25: Sep–Oct | C25: 1 | D25: 10.5 | E25: 160 | F25: 4.5 | G25: 3.5
A26: Barley pasture (winter) | B26: May–Aug | C26: 1.1 | D26: 11 | E26: 154 | F26: 4.4 | G26: 3.3
A27: Natural veld (good, green) | B27: Mar–May | C27: 1 | D27: 7.5 | E27: 60 | F27: 3 | G27: 1.5
A28: Natural veld (dry, dormant) | B28: Jun–Sep | C28: 0.8 | D28: 6 | E28: 48 | F28: 2.4 | G28: 1.2
A29: Natural veld + rye mix | B29: Apr–Jun | C29: 1.1 | D29: 9.5 | E29: 110 | F29: 4 | G29: 2.5
A30: Lucerne pasture (irrigated) | B30: Year-round | C30: 1.3 | D30: 11.1 | E30: 234 | F30: 18.2 | G30: 3.3
A32: SUPPLEMENT GAP ANALYSIS — What the supplement must provide (Total Need – Grazing Contribution)
A33: This shows the gap between what grazing provides and what the ewe needs. The supplement must fill this gap.
A34: Phase | B34: Grazing Assumed | C34: Total ME Need (MJ/d) | D34: Grazing ME (MJ/d) | E34: ME Gap (MJ/d) | F34: Total CP Need (g/d) | G34: Grazing CP (g/d) | H34: CP Gap (g/d) | I34: Supp Rate (g/d) | J34: Supp ME (MJ/kg) | K34: Supp CP (% DM) | L34: Adequate?
A35: 1. Mid Preg (Twins) | B35: Veld (green, Feb–Apr) | C35: 8.9 | D35: 7.5 | E35: 1.4 | F35: 122 | G35: 60 | H35: 62 | I35: 250 | J35: 5.6 | K35: 24.8
A36: 1. Mid Preg (Singles) | B36: Veld (green, Feb–Apr) | C36: 8.9 | D36: 7.5 | E36: 1.4 | F36: 122 | G36: 60 | H36: 62 | I36: 150 | J36: 9.3 | K36: 41.3
A37: 2. Late Preg (Twins) | B37: Veld + rye pasture (Apr–May) | C37: 14.4 | D37: 9.5 | E37: 4.9 | F37: 204 | G37: 110 | H37: 94 | I37: 450 | J37: 10.9 | K37: 20.9
A38: 2. Late Preg (Singles) | B38: Veld + rye pasture (Apr–May) | C38: 12.2 | D38: 9.5 | E38: 2.7 | F38: 181 | G38: 110 | H38: 71 | I38: 280 | J38: 9.6 | K38: 25.4
A39: 3. Early Lact (Twins) | B39: Rye pasture (May–Jun, peak growth) | C39: 20.5 | D39: 12.6 | E39: 7.9 | F39: 404 | G39: 192 | H39: 212 | I39: 600 | J39: 13.2 | K39: 35.3
A40: 3. Early Lact (Singles) | B40: Rye pasture (May–Jun, peak growth) | C40: 18.3 | D40: 12.6 | E40: 5.7 | F40: 318 | G40: 192 | H40: 126 | I40: 400 | J40: 14.3 | K40: 31.5
A41: 4. Peak Lact (Twins) | B41: Rye pasture (Jun–Jul, peak growth) | C41: 20.5 | D41: 12.6 | E41: 7.9 | F41: 404 | G41: 192 | H41: 212 | I41: 600 | J41: 13.2 | K41: 35.3
A42: 4. Peak Lact (Singles) | B42: Rye pasture (Jun–Jul, peak growth) | C42: 18.3 | D42: 12.6 | E42: 5.7 | F42: 318 | G42: 192 | H42: 126 | I42: 400 | J42: 14.3 | K42: 31.5
A43: 5. Weaners | B43: Rye/barley pasture (Aug–Sep) | C43: 10.9 | D43: 10.5 | E43: 0.4 | F43: 177 | G43: 160 | H43: 17 | I43: 280 | J43: 1.4 | K43: 6.1
A44: 6. Flushing | B44: Spring veld (Sep–Oct) | C44: 12.2 | D44: 7.5 | E44: 4.7 | F44: 154 | G44: 60 | H44: 94 | I44: 250 | J44: 18.8 | K44: 37.6
A46: KEY FINDINGS FROM GAP ANALYSIS:
...

Sheet Flock Calculator
A1: FLOCK FEEDING CALCULATOR
A2: Enter flock numbers — all calculations update automatically
A4: FLOCK NUMBERS — ENTER COUNTS
A5: Category | B5: Head Count | C5: Description
A6: Twin-bearing ewes | B6: 250 | C6: From scanning
A7: Single-bearing ewes | B7: 450 | C7: From scanning
A8: Dry / open ewes | B8: 30 | C8: Not pregnant
A9: Replacement ewes (maiden) | B9: 200 | C9: Not yet joined
A10: Weaners (post-weaning) | B10: 0 | C10: Enter once weaned
A11: Rams | B11: 25 | C11: Breeding rams
A12: TOTAL FLOCK | B12: =SUM(B6:B11) -> 955
A14: FEEDING PHASES WITH NRC-VALIDATED TARGETS
A15: Phase | B15: Period | C15: Group | D15: ME Target (MJ/d) | E15: CP Target (g/d) | F15: Supplement (g/d) | G15: Roughage Basis | H15: Head Count
A16: 1. Mid Pregnancy | B16: Feb–Apr | C16: Twin-bearers | D16: 8.9 | E16: 122 | F16: 300 | G16: Natural veld (green season) | H16: =$B$6 -> 250
A17: 1. Mid Pregnancy | B17: Feb–Apr | C17: Single-bearers | D17: 8.9 | E17: 122 | F17: 200 | G17: Natural veld (green season) | H17: =$B$7 -> 450
A18: 1. Mid Pregnancy | B18: Feb–Apr | C18: Dry / Open | D18: 7.2 | E18: 104 | F18: 0 | G18: Maintenance veld + lick | H18: =$B$8 -> 30
A19: 1. Mid Pregnancy | B19: Feb–Apr | C19: Replacements | D19: 10 | E19: 136 | F19: 200 | G19: Good veld + supplement | H19: =$B$9 -> 200
A20: 2. Late Pregnancy | B20: Apr–May | C20: Twin-bearers | D20: 14.4 | E20: 204 | F20: 500 | G20: Veld + rye/barley pasture | H20: =$B$6 -> 250
A21: 2. Late Pregnancy | B21: Apr–May | C21: Single-bearers | D21: 12.2 | E21: 181 | F21: 300 | G21: Veld + rye pasture | H21: =$B$7 -> 450
A22: 3. Lambing + Early Lact. | B22: May–Jun | C22: Twin-rearing | D22: 20.5 | E22: 404 | F22: 800 | G22: Best rye pasture + 1kg lucerne hay/day | H22: =$B$6 -> 250
A23: 3. Lambing + Early Lact. | B23: May–Jun | C23: Single-rearing | D23: 18.3 | E23: 318 | F23: 500 | G23: Good rye pasture + lucerne hay if thin | H23: =$B$7 -> 450
A24: 4. Peak Lactation | B24: Jun–Jul | C24: Twin-rearing | D24: 20.5 | E24: 404 | F24: 800 | G24: Best rye pasture + 1kg lucerne hay/day | H24: =$B$6 -> 250
A25: 4. Peak Lactation | B25: Jun–Jul | C25: Single-rearing | D25: 18.3 | E25: 318 | F25: 500 | G25: Good rye pasture + lucerne hay if thin | H25: =$B$7 -> 450
A26: 4. Peak Lactation | B26: Jun–Jul | C26: Weaners (creep) | D26: 10.9 | E26: 177 | F26: 300 | G26: Rye/barley pasture + creep | H26: =$B$10 -> 0
A27: 5. Weaning | B27: Aug–Sep | C27: Ewes (all) | D27: 8.5 | E27: 120 | F27: 150 | G27: Rye pasture maintenance | H27: =$B$6+$B$7 -> 700
A28: 5. Weaning | B28: Aug–Sep | C28: Weaners | D28: 10.9 | E28: 177 | F28: 300 | G28: Best pasture + grower | H28: =$B$10 -> 0
A29: 6. Dry / Flushing | B29: Sep–Oct | C29: All ewes | D29: 12.2 | E29: 154 | F29: 500 | G29: Spring veld + flushing feed | H29: =$B$6+$B$7+$B$8 -> 730
A30: 6. Dry / Flushing | B30: Sep–Oct | C30: Replacements | D30: 12.2 | E30: 154 | F30: 500 | G30: Flushing + growth | H30: =$B$9 -> 200
A31: 6. Dry / Flushing | B31: Sep–Oct | C31: Rams | D31: 14.4 | E31: 190 | F31: 400 | G31: Condition for joining | H31: =$B$11 -> 25
A33: DAILY FEED TOTALS BY PHASE
A34: Phase | B34: Period | C34: Total Head | D34: Supplement (kg/day) | E34: Supplement (kg/month) | F34: Est. Monthly Cost (R)
A35: 1. Mid Pregnancy | B35: Feb–Apr | C35: =H16+H17+H18+H19 -> 930 | D35: =(F16*H16+F17*H17+F18*H18+F19*H19)/1000 -> 205 | E35: =D35*30 -> 6150 | F35: =E35*4.5 -> 27675
A36: 2. Late Pregnancy | B36: Apr–May | C36: =H20+H21 -> 700 | D36: =(F20*H20+F21*H21)/1000 -> 260 | E36: =D36*30 -> 7800 | F36: =E36*4.5 -> 35100
A37: 3. Lambing + Early Lact. | B37: May–Jun | C37: =H22+H23 -> 700 | D37: =(F22*H22+F23*H23)/1000 -> 425 | E37: =D37*30 -> 12750 | F37: =E37*4.5 -> 57375
A38: 4. Peak Lactation | B38: Jun–Jul | C38: =H24+H25+H26 -> 700 | D38: =(F24*H24+F25*H25+F26*H26)/1000 -> 425 | E38: =D38*30 -> 12750 | F38: =E38*4.5 -> 57375
A39: 5. Weaning | B39: Aug–Sep | C39: =H27+H28 -> 700 | D39: =(F27*H27+F28*H28)/1000 -> 105 | E39: =D39*30 -> 3150 | F39: =E39*4.5 -> 14175
A40: 6. Dry / Flushing | B40: Sep–Oct | C40: =H29+H30+H31 -> 955 | D40: =(F29*H29+F30*H30+F31*H31)/1000 -> 475 | E40: =D40*30 -> 14250 | F40: =E40*4.5 -> 64125
A41: ANNUAL (sum all months) | E41: =SUM(E35:E40) -> 56850 | F41: =SUM(F35:F40) -> 255825

Sheet Mix Designer
A1: RATION MIX DESIGNER — NRC-VALIDATED
A2: Mixes redesigned to meet NRC gap analysis targets. Enter inclusion rates (kg/100kg) — results calculate automatically.
A4: Phase 1: Mid Pregnancy (300g/d for twins, 200g/d singles)
A5: Gap target: ≥9.0 MJ/kg ME, ≥15% CP — low-spec, veld does most work | C5: Supplement rate (g/head/day): | E5: 300 | F5: Head count: | G5: ='Flock Calculator'!$B$6 -> 250
A6: Ingredient | B6: kg/100kg | C6: ME (MJ/kg) | D6: CP (%) | E6: Cost (R/kg) | F6: ME contrib. | G6: CP contrib. | H6: Cost contrib. | I6: Ca contrib. | J6: P contrib.
A7: Barley grain (own) | B7: 22 | C7: ='Feed Ingredients'!C6 -> 12.8 | D7: ='Feed Ingredients'!D6 -> 11.5 | E7: ='Feed Ingredients'!H6 -> 3.2 | F7: =B7/100*C7 -> 2.816 | G7: =B7/100*D7 -> 2.53 | H7: =B7/100*E7 -> 0.704 | I7: =B7/100*'Feed Ingredients'!F6 -> 0.011 | J7: =B7/100*'Feed Ingredients'!G6 -> 0.077
A8: Wheat grain (own) | B8: 0 | C8: ='Feed Ingredients'!C7 -> 13.2 | D8: ='Feed Ingredients'!D7 -> 12.5 | E8: ='Feed Ingredients'!H7 -> 4 | F8: =B8/100*C8 -> 0 | G8: =B8/100*D8 -> 0 | H8: =B8/100*E8 -> 0 | I8: =B8/100*'Feed Ingredients'!F7 -> 0 | J8: =B8/100*'Feed Ingredients'!G7 -> 0
A9: Lupins (own) | B9: 28 | C9: ='Feed Ingredients'!C8 -> 12 | D9: ='Feed Ingredients'!D8 -> 32 | E9: ='Feed Ingredients'!H8 -> 5.5 | F9: =B9/100*C9 -> 3.36 | G9: =B9/100*D9 -> 8.96 | H9: =B9/100*E9 -> 1.54 | I9: =B9/100*'Feed Ingredients'!F8 -> 0.07 | J9: =B9/100*'Feed Ingredients'!G8 -> 0.112
A10: Maize meal | B10: 8 | C10: ='Feed Ingredients'!C10 -> 13.8 | D10: ='Feed Ingredients'!D10 -> 9 | E10: ='Feed Ingredients'!H10 -> 4.8 | F10: =B10/100*C10 -> 1.104 | G10: =B10/100*D10 -> 0.72 | H10: =B10/100*E10 -> 0.384 | I10: =B10/100*'Feed Ingredients'!F10 -> 0.0024 | J10: =B10/100*'Feed Ingredients'!G10 -> 0.0224
A11: Lucerne hay (own) | B11: 15 | C11: ='Feed Ingredients'!C9 -> 8.5 | D11: ='Feed Ingredients'!D9 -> 18 | E11: ='Feed Ingredients'!H9 -> 2.8 | F11: =B11/100*C11 -> 1.275 | G11: =B11/100*D11 -> 2.7 | H11: =B11/100*E11 -> 0.42 | I11: =B11/100*'Feed Ingredients'!F9 -> 0.21 | J11: =B11/100*'Feed Ingredients'!G9 -> 0.0375
A12: Cottonseed oilcake | B12: 10 | C12: ='Feed Ingredients'!C13 -> 11.5 | D12: ='Feed Ingredients'!D13 -> 41 | E12: ='Feed Ingredients'!H13 -> 6.5 | F12: =B12/100*C12 -> 1.15 | G12: =B12/100*D12 -> 4.1 | H12: =B12/100*E12 -> 0.65 | I12: =B12/100*'Feed Ingredients'!F13 -> 0.02 | J12: =B12/100*'Feed Ingredients'!G13 -> 0.11
A13: Molasses meal | B13: 8 | C13: ='Feed Ingredients'!C12 -> 10.5 | D13: ='Feed Ingredients'!D12 -> 5 | E13: ='Feed Ingredients'!H12 -> 2.5 | F13: =B13/100*C13 -> 0.84 | G13: =B13/100*D13 -> 0.4 | H13: =B13/100*E13 -> 0.2 | I13: =B13/100*'Feed Ingredients'!F12 -> 0.072 | J13: =B13/100*'Feed Ingredients'!G12 -> 0.008
A14: Sunflower oilcake | B14: 3 | C14: ='Feed Ingredients'!C14 -> 10 | D14: ='Feed Ingredients'!D14 -> 34 | E14: ='Feed Ingredients'!H14 -> 5.8 | F14: =B14/100*C14 -> 0.3 | G14: =B14/100*D14 -> 1.02 | H14: =B14/100*E14 -> 0.174 | I14: =B14/100*'Feed Ingredients'!F14 -> 0.0105 | J14: =B14/100*'Feed Ingredients'!G14 -> 0.03
A15: Salt (NaCl) | B15: 1.5 | C15: ='Feed Ingredients'!C18 -> 0 | D15: ='Feed Ingredients'!D18 -> 0 | E15: ='Feed Ingredients'!H18 -> 1.2 | F15: =B15/100*C15 -> 0 | G15: =B15/100*D15 -> 0 | H15: =B15/100*E15 -> 0.018 | I15: =B15/100*'Feed Ingredients'!F18 -> 0 | J15: =B15/100*'Feed Ingredients'!G18 -> 0
A16: Feed lime | B16: 1.5 | C16: ='Feed Ingredients'!C19 -> 0 | D16: ='Feed Ingredients'!D19 -> 0 | E16: ='Feed Ingredients'!H19 -> 0.8 | F16: =B16/100*C16 -> 0 | G16: =B16/100*D16 -> 0 | H16: =B16/100*E16 -> 0.012 | I16: =B16/100*'Feed Ingredients'!F19 -> 0.57 | J16: =B16/100*'Feed Ingredients'!G19 -> 0
A17: Monocalcium phosphate | B17: 1 | C17: ='Feed Ingredients'!C20 -> 0 | D17: ='Feed Ingredients'!D20 -> 0 | E17: ='Feed Ingredients'!H20 -> 12 | F17: =B17/100*C17 -> 0 | G17: =B17/100*D17 -> 0 | H17: =B17/100*E17 -> 0.12 | I17: =B17/100*'Feed Ingredients'!F20 -> 0.16 | J17: =B17/100*'Feed Ingredients'!G20 -> 0.21
A18: Vit/mineral premix | B18: 1 | C18: ='Feed Ingredients'!C21 -> 0 | D18: ='Feed Ingredients'!D21 -> 0 | E18: ='Feed Ingredients'!H21 -> 35 | F18: =B18/100*C18 -> 0 | G18: =B18/100*D18 -> 0 | H18: =B18/100*E18 -> 0.35 | I18: =B18/100*'Feed Ingredients'!F21 -> 0 | J18: =B18/100*'Feed Ingredients'!G21 -> 0
A19: TOTAL MIX | B19: =SUM(B7:B18) -> 99 | F19: =SUM(F7:F18) -> 10.845 | G19: =SUM(G7:G18) -> 20.43 | H19: =SUM(H7:H18) -> 4.572 | I19: =SUM(I7:I18) -> 1.1259 | J19: =SUM(J7:J18) -> 0.6069
A20: Mix ME (MJ/kg): | B20: =F19 -> 10.845 | C20: Mix CP (%): | D20: =G19 -> 20.43 | E20: Cost/kg (R): | F20: =H19 -> 4.572 | G20: Ca:P ratio: | H20: =IF(J19=0,"N/A",I19/J19) -> 1.8551656
A21: Cost per head/day (R): | B21: =H19*E5/1000 -> 1.3716 | C21: Daily flock cost (R): | D21: =B21*G5 -> 342.9 | E21: Monthly cost (R): | F21: =D21*30 -> 10287
A22: ME delivered/head/day (MJ): | B22: =F19*E5/1000 -> 3.2535 | C22: CP delivered/head/day (g): | D22: =G19*E5/100 -> 61.29
A24: Phase 2: Late Pregnancy (500g/d twins, 300g/d singles)
A25: Gap target: ≥11.0 MJ/kg ME, ≥19% CP — energy critical, prevent twin lamb disease | C25: Supplement rate (g/head/day): | E25: 500 | F25: Head count: | G25: ='Flock Calculator'!$B$6 -> 250
A26: Ingredient | B26: kg/100kg | C26: ME (MJ/kg) | D26: CP (%) | E26: Cost (R/kg) | F26: ME contrib. | G26: CP contrib. | H26: Cost contrib. | I26: Ca contrib. | J26: P contrib.
A27: Barley grain (own) | B27: 22 | C27: ='Feed Ingredients'!C6 -> 12.8 | D27: ='Feed Ingredients'!D6 -> 11.5 | E27: ='Feed Ingredients'!H6 -> 3.2 | F27: =B27/100*C27 -> 2.816 | G27: =B27/100*D27 -> 2.53 | H27: =B27/100*E27 -> 0.704 | I27: =B27/100*'Feed Ingredients'!F6 -> 0.011 | J27: =B27/100*'Feed Ingredients'!G6 -> 0.077
A28: Wheat grain (own) | B28: 10 | C28: ='Feed Ingredients'!C7 -> 13.2 | D28: ='Feed Ingredients'!D7 -> 12.5 | E28: ='Feed Ingredients'!H7 -> 4 | F28: =B28/100*C28 -> 1.32 | G28: =B28/100*D28 -> 1.25 | H28: =B28/100*E28 -> 0.4 | I28: =B28/100*'Feed Ingredients'!F7 -> 0.005 | J28: =B28/100*'Feed Ingredients'!G7 -> 0.04
A29: Lupins (own) | B29: 24 | C29: ='Feed Ingredients'!C8 -> 12 | D29: ='Feed Ingredients'!D8 -> 32 | E29: ='Feed Ingredients'!H8 -> 5.5 | F29: =B29/100*C29 -> 2.88 | G29: =B29/100*D29 -> 7.68 | H29: =B29/100*E29 -> 1.32 | I29: =B29/100*'Feed Ingredients'!F8 -> 0.06 | J29: =B29/100*'Feed Ingredients'!G8 -> 0.096
A30: Maize meal | B30: 15 | C30: ='Feed Ingredients'!C10 -> 13.8 | D30: ='Feed Ingredients'!D10 -> 9 | E30: ='Feed Ingredients'!H10 -> 4.8 | F30: =B30/100*C30 -> 2.07 | G30: =B30/100*D30 -> 1.35 | H30: =B30/100*E30 -> 0.72 | I30: =B30/100*'Feed Ingredients'!F10 -> 0.0045 | J30: =B30/100*'Feed Ingredients'!G10 -> 0.042
A31: Lucerne hay (own) | B31: 5 | C31: ='Feed Ingredients'!C9 -> 8.5 | D31: ='Feed Ingredients'!D9 -> 18 | E31: ='Feed Ingredients'!H9 -> 2.8 | F31: =B31/100*C31 -> 0.425 | G31: =B31/100*D31 -> 0.9 | H31: =B31/100*E31 -> 0.14 | I31: =B31/100*'Feed Ingredients'!F9 -> 0.07 | J31: =B31/100*'Feed Ingredients'!G9 -> 0.0125
A32: Cottonseed oilcake | B32: 12 | C32: ='Feed Ingredients'!C13 -> 11.5 | D32: ='Feed Ingredients'!D13 -> 41 | E32: ='Feed Ingredients'!H13 -> 6.5 | F32: =B32/100*C32 -> 1.38 | G32: =B32/100*D32 -> 4.92 | H32: =B32/100*E32 -> 0.78 | I32: =B32/100*'Feed Ingredients'!F13 -> 0.024 | J32: =B32/100*'Feed Ingredients'!G13 -> 0.132
A33: Molasses meal | B33: 5 | C33: ='Feed Ingredients'!C12 -> 10.5 | D33: ='Feed Ingredients'!D12 -> 5 | E33: ='Feed Ingredients'!H12 -> 2.5 | F33: =B33/100*C33 -> 0.525 | G33: =B33/100*D33 -> 0.25 | H33: =B33/100*E33 -> 0.125 | I33: =B33/100*'Feed Ingredients'!F12 -> 0.045 | J33: =B33/100*'Feed Ingredients'!G12 -> 0.005
A34: Sunflower oilcake | B34: 2 | C34: ='Feed Ingredients'!C14 -> 10 | D34: ='Feed Ingredients'!D14 -> 34 | E34: ='Feed Ingredients'!H14 -> 5.8 | F34: =B34/100*C34 -> 0.2 | G34: =B34/100*D34 -> 0.68 | H34: =B34/100*E34 -> 0.116 | I34: =B34/100*'Feed Ingredients'!F14 -> 0.007 | J34: =B34/100*'Feed Ingredients'!G14 -> 0.02
A35: Salt (NaCl) | B35: 1.5 | C35: ='Feed Ingredients'!C18 -> 0 | D35: ='Feed Ingredients'!D18 -> 0 | E35: ='Feed Ingredients'!H18 -> 1.2 | F35: =B35/100*C35 -> 0 | G35: =B35/100*D35 -> 0 | H35: =B35/100*E35 -> 0.018 | I35: =B35/100*'Feed Ingredients'!F18 -> 0 | J35: =B35/100*'Feed Ingredients'!G18 -> 0
A36: Feed lime | B36: 1.5 | C36: ='Feed Ingredients'!C19 -> 0 | D36: ='Feed Ingredients'!D19 -> 0 | E36: ='Feed Ingredients'!H19 -> 0.8 | F36: =B36/100*C36 -> 0 | G36: =B36/100*D36 -> 0 | H36: =B36/100*E36 -> 0.012 | I36: =B36/100*'Feed Ingredients'!F19 -> 0.57 | J36: =B36/100*'Feed Ingredients'!G19 -> 0
A37: Monocalcium phosphate | B37: 1 | C37: ='Feed Ingredients'!C20 -> 0 | D37: ='Feed Ingredients'!D20 -> 0 | E37: ='Feed Ingredients'!H20 -> 12 | F37: =B37/100*C37 -> 0 | G37: =B37/100*D37 -> 0 | H37: =B37/100*E37 -> 0.12 | I37: =B37/100*'Feed Ingredients'!F20 -> 0.16 | J37: =B37/100*'Feed Ingredients'!G20 -> 0.21
A38: Vit/mineral premix | B38: 1 | C38: ='Feed Ingredients'!C21 -> 0 | D38: ='Feed Ingredients'!D21 -> 0 | E38: ='Feed Ingredients'!H21 -> 35 | F38: =B38/100*C38 -> 0 | G38: =B38/100*D38 -> 0 | H38: =B38/100*E38 -> 0.35 | I38: =B38/100*'Feed Ingredients'!F21 -> 0 | J38: =B38/100*'Feed Ingredients'!G21 -> 0
A39: TOTAL MIX | B39: =SUM(B27:B38) -> 100 | F39: =SUM(F27:F38) -> 11.616 | G39: =SUM(G27:G38) -> 19.56 | H39: =SUM(H27:H38) -> 4.805 | I39: =SUM(I27:I38) -> 0.9565 | J39: =SUM(J27:J38) -> 0.6345
A40: Mix ME (MJ/kg): | B40: =F39 -> 11.616 | C40: Mix CP (%): | D40: =G39 -> 19.56 | E40: Cost/kg (R): | F40: =H39 -> 4.805 | G40: Ca:P ratio: | H40: =IF(J39=0,"N/A",I39/J39) -> 1.5074862
A41: Cost per head/day (R): | B41: =H39*E25/1000 -> 2.4025 | C41: Daily flock cost (R): | D41: =B41*G25 -> 600.625 | E41: Monthly cost (R): | F41: =D41*30 -> 18018.75
A42: ME delivered/head/day (MJ): | B42: =F39*E25/1000 -> 5.808 | C42: CP delivered/head/day (g): | D42: =G39*E25/100 -> 97.8
...

Sheet Cost Summary
A1: ANNUAL FEEDING COST SUMMARY
A2: All values linked to Mix Designer and Flock Calculator
A4: MONTHLY COST BY PHASE
A5: Phase | B5: Period | C5: Duration (months) | D5: Head Count | E5: Monthly Feed Cost (R) | F5: Phase Total (R) | G5: % of Annual
A6: 1. Mid Pregnancy | B6: Feb–Apr | C6: 2.5 | D6: ='Mix Designer'!G5 -> 250 | E6: ='Mix Designer'!F21 -> 10287 | F6: =E6*C6 -> 25717.5 | G6: =IF(F$12=0,0,F6/F$12) -> 0.096776515
A7: 2. Late Pregnancy | B7: Apr–May | C7: 1.5 | D7: ='Mix Designer'!G25 -> 250 | E7: ='Mix Designer'!F41 -> 18018.75 | F7: =E7*C7 -> 27028.125 | G7: =IF(F$12=0,0,F7/F$12) -> 0.10170848
A8: 3. Lambing/Early Lact. | B8: May–Jun | C8: 1.5 | D8: ='Mix Designer'!G45 -> 250 | E8: ='Mix Designer'!F61 -> 31854 | F8: =E8*C8 -> 47781 | G8: =IF(F$12=0,0,F8/F$12) -> 0.17980281
A9: 4. Peak Lactation | B9: Jun–Jul | C9: 2 | D9: ='Mix Designer'!G65 -> 250 | E9: ='Mix Designer'!F81 -> 31854 | F9: =E9*C9 -> 63708 | G9: =IF(F$12=0,0,F9/F$12) -> 0.23973707
A10: 5. Weaning | B10: Aug–Sep | C10: 2 | D10: ='Mix Designer'!G85 -> 0 | E10: ='Mix Designer'!F101 -> 0 | F10: =E10*C10 -> 0 | G10: =IF(F$12=0,0,F10/F$12) -> 0
A11: 6. Flushing | B11: Sep–Oct | C11: 2 | D11: ='Mix Designer'!G105 -> 730 | E11: ='Mix Designer'!F121 -> 50753.25 | F11: =E11*C11 -> 101506.5 | G11: =IF(F$12=0,0,F11/F$12) -> 0.38197513
A12: ANNUAL TOTAL | F12: =SUM(F6:F11) -> 265741.12
A14: KEY METRICS
A15: Total pregnant ewes: | B15: ='Flock Calculator'!B6+'Flock Calculator'!B7 -> 700
A16: Annual feed cost per pregnant ewe: | B16: =IF(B15=0,0,F12/B15) -> 379.63018
A17: Cost per head total flock: | B17: =IF('Flock Calculator'!B12=0,0,F12/'Flock Calculator'!B12) -> 278.26296
A18: Average daily spend (R): | B18: =F12/365 -> 728.05788

Sheet Grazing Planner
A1: GRAZING & PASTURE PLANNER
A2: Pasture allocation — sheep graze bulk roughage from the land, supplement fills the gap
A4: PASTURE INPUTS
A5: Parameter | B5: Value | C5: Notes
A6: Total rye pasture (ha) | B6: 80 | C6: Hectares planted to rye
A7: Total barley pasture (ha) | B7: 60 | C7: Hectares planted to barley
A8: Wheat stubble (ha) | B8: 40 | C8: Post-harvest grazing
A9: Natural veld (ha) | B9: 500 | C9: Natural grazing
A10: Lucerne under irrigation (ha) | B10: 20 | C10: Cut/grazed
A11: Veld carrying capacity (ha/LSU) | B11: 8 | C11: Northern Cape semi-arid
A12: Improved pasture capacity (ha/LSU) | B12: 2 | C12: Irrigated/dryland improved
A14: CARRYING CAPACITY
A15: 1 LSU = ~6 dry Dohne ewes or ~4 ewes with lambs at foot
A16: Veld LSU capacity | B16: =B9/B11 -> 62.5
A17: Veld ewe capacity (with lambs) | B17: =B16*4 -> 250
A18: Improved pasture LSU | B18: =(B6+B7)/B12 -> 70
A19: Improved pasture ewes (with lambs) | B19: =B18*4 -> 280
A20: Total capacity (ewes+lambs) | B20: =B17+B19 -> 530
A21: Current flock | B21: ='Flock Calculator'!B6+'Flock Calculator'!B7+'Flock Calculator'!B9 -> 900
A22: Surplus / (Deficit) | B22: =B20-B21 -> -370
