Workbook

Sheet Forecasted January 2021
E4: Diverse Costs | F4: Difference | G4: Forecasted Full 2020/2021 | H4: 2020/2021 (Incomplete) | I4: 2019/2020 | J4: 2018/2019
E5: Bank costs | F5: =G5-H5 -> 750.798 | G5: =H5*1.3 -> 3253.458 | H5: 2502.66 | I5: 1266.21 | J5: 5090.79
E6: Bemarkingskostes | F6: =G6-H6 -> -12656.62 | H6: 12656.62 | I6: 10357.33 | J6: 26518.21
E7: Bemesting and Gifstowwe | F7: =G7-H7 -> 355727.28 | G7: =H7*2 -> 711454.56 | H7: 355727.28 | I7: 415528.13 | J7: 674535.45
E8: Protective Clothing | F8: =G8-H8 -> 6480 | G8: =H8*5 -> 8100 | H8: 1620 | I8: 1595.02 | J8: 1563.9
E9: Diesel | F9: =G9-H9 -> 266965.1 | G9: =H9*2 -> 533930.2 | H9: 266965.1 | I9: 524450.34 | J9: 567176.87
E10: Skryfbehoeftes | F10: =G10-H10 -> 613.321 | G10: =H10*1.1 -> 6746.531 | H10: 6133.21 | I10: 6606.09 | J10: 8026.86
C11: =G11 -> 47107.52 | D11: 1 | E11: Electricity | F11: =G11-H11 -> 1193.18 | G11: =I11 -> 47107.52 | H11: 45914.34 | I11: 47107.52 | J11: 41678.31
E12: Erfelasting | F12: =G12-H12 -> 6782.38 | G12: =J12 -> 6782.38 | I12: 3615.84 | J12: 6782.38
E13: Finansieringskostes | F13: =G13-H13 -> -1015.12 | G13: =J13 -> 1228.67 | H13: 2243.79 | I13: 1624.65 | J13: 1228.67
E14: Huurbetaal | F14: =G14-H14 -> #REF! | G14: =I14 -> 178428.08 | H14: =Sheet1!B215 -> #REF! | I14: 178428.08 | J14: 174034.59
E15: Instandhouding - Besproeing | F15: =G15-H15 -> #REF! | G15: 10000 | H15: =Sheet1!B220 -> #REF! | I15: -26646.98 | J15: 66888
C16: =G16 -> 1016373.6 | D16: 1 | E16: Instandhouding - Implemente en Toerusting | F16: =G16-H16 -> 0 | G16: =H16 -> 1016373.6 | H16: 1016373.6 | I16: 1076544.6 | J16: 997009.07
C17: =G17 -> 24000 | D17: 1 | E17: Kommunikasiekostes - Selluler | F17: =G17-H17 -> 13816 | G17: 24000 | H17: 10184 | I17: 13930.17
E18: Kommunikasiekostes - Posgeld | F18: =G18-H18 -> 0 | I18: 26552.18 | J18: 430.43
C19: =G19 -> 13043.48 | D19: 1 | E19: Kommunikasiekostes - Internet | F19: =G19-H19 -> 0 | G19: =H19 -> 13043.48 | H19: 13043.48 | J19: 368.42
C20: =G20 -> 13043.48 | D20: 1 | E20: Kommunikasiekostes - Telefoon | F20: =G20-H20 -> 0 | G20: =H20 -> 13043.48 | H20: 13043.48 | I20: 32340.95 | J20: 7041.85
C21: =G21 -> 15354.72 | D21: 1 | E21: Ledegelde | F21: =G21-H21 -> 0 | G21: =H21 -> 15354.72 | H21: 15354.72 | I21: 7945.75 | J21: 7524.03
C22: =G22 -> #REF! | D22: 1 | E22: Lisensies | F22: =G22-H22 -> #REF! | G22: =H22 -> #REF! | H22: =Sheet1!B346 -> #REF! | I22: 19248 | J22: 16597.97
E23: Oesdeel | F23: =G23-H23 -> 300000 | G23: 300000 | I23: 778171.02 | J23: 1105670.2
C24: =G24 -> 110000 | D24: 1 | E24: Oeskoste van Druiwe | F24: =G24-H24 -> 110000 | G24: 110000 | I24: 39000 | J24: 112294.5
E25: Regskostes- Skuldinvordering | F25: =G25-H25 -> #REF! | G25: =H25 -> #REF! | H25: =Sheet1!B354 -> #REF! | I25: 743.48
E26: Regskostes- Kapitale uitgawes | F26: =G26-H26 -> 0 | G26: =H26 | J26: 297.39
E27: Reis en Verblyf: Plaaslik | F27: =G27-H27 -> 0 | G27: =H27 | I27: 9000 | J27: 12000
E28: Reis en Verblyf: Buiteland | F28: =G28-H28 -> 0 | G28: =H28 | J28: 4538.63
E29: Rekenmeestergelde | F29: =G29-H29 -> 15178.03 | G29: =I29 -> 39008.03 | H29: 23830 | I29: 39008.03 | J29: 41340.7 | M29: Forecasted
E30: Saad & Plantmateriaal | F30: =G30-H30 -> #REF! | G30: =H30 -> #REF! | H30: =Sheet1!B376 -> #REF! | I30: 10200 | K30: =SUM(H31:H37) -> #REF! | L30: S&L 2020 | M30: =K30*1.5 -> #REF! | N30: S&L Full 2020
C31: =G31 -> 100000 | D31: 1 | E31: S & L - Salarisse | F31: =G31-H31 -> 19793 | G31: 100000 | H31: 80207 | I31: 147324.36 | J31: 49944.56 | K31: =SUM(I31:I37) -> 2820749 | L31: S&L 2019
C32: =G32 -> 700000 | D32: 1 | E32: S & L - Lone | F32: =G32-H32 -> 150666.04 | G32: 700000 | H32: 549333.96 | I32: 1874669.3 | J32: 1251680.1 | K32: =SUM(J31:J37) -> 1721624.6 | L32: S&L 2018 | M32: =1313687.94/200000 -> 6.5684397
C33: =G33 -> #REF! | D33: 1 | E33: S & L - Werkloosheidsversekering | F33: =G33-H33 -> #REF! | G33: =0.015*M30 -> #REF! | H33: =Sheet1!B505 -> #REF! | I33: 14582 | J33: 28119.56
C34: =G34 -> 450000 | D34: 1 | E34: S & L - Rantsoene | F34: =G34-H34 -> 53345.77 | G34: 450000 | H34: 396654.23 | I34: 718768.19 | J34: 362884.46 | K34: =K32*0.015 -> 25824.37
C35: =G35 -> 20000 | D35: 1 | E35: S & L - Personeelvoordele | F35: =G35-H35 -> 4066.77 | G35: 20000 | H35: 15933.23 | I35: 47459.5 | J35: 23395.94
C36: =G36 -> 102691.92 | D36: 1 | E36: S & L - Teesaad | F36: =G36-H36 -> 10000 | G36: =H36+10000 -> 102691.92 | H36: 92691.92 | I36: 17945.61 | J36: 5600 | K36: =SUM(G31:G37) -> #REF!
C37: =G37 | D37: 1 | E37: S & L - Ongevalleversekering | F37: =G37-H37 -> #REF! | H37: =Sheet1!B566 -> #REF!
E38: Sekuriteit | F38: =G38-H38 -> #REF! | G38: 4000 | H38: =Sheet1!B585 -> #REF! | I38: 2466.44 | J38: 31195.13 | K38: =K36-K30 -> #REF!
C39: =G39 -> 16000 | D39: 1 | E39: Veemedisyne en -doserings | F39: =G39-H39 -> -3023.99 | G39: 16000 | H39: 19023.99 | I39: 20059.27 | J39: 4006.57
E40: Veevoer | F40: =G40-H40 -> 4000 | G40: =H40+4000 -> 165397.1 | H40: 161397.1 | I40: 79496.69 | J40: 28508.16
E41: Verbeteringe - Aanplantings en opleiding | F41: =G41-H41 -> 0 | G41: =H41 | I41: 463250.86 | J41: -126537.2
E42: Verbeteringe - Geboue | F42: =G42-H42 -> 10000 | G42: 10000 | I42: 504906.93
E43: Verpakkingsmateriaal | F43: =G43-H43 -> 10000 | G43: 10000 | I43: 9385.6 | J43: 8888.35
...

Sheet Farms
A1: ID | B1: Farm Name | C1: Status | D1: Relationship | E1: Province/District | F1: Title Deed / Notes | G1: Nearest Town | H1: Distance from Cloudskraal (km) | I1: Size (ha) | J1: Primary Enterprise | K1: Annual Production Capacity | L1: Water Source | M1: Power | N1: Key Infrastructure | O1: Soil/Topo Notes | P1: GPS (lat,lon) | Q1: Ownership/Counterparty | R1: Contact | S1: Deal Terms | T1: Capex Needed (R) | U1: Opex/Yr (R) | V1: Target ROI/IRR (%) | W1: Strategic Fit | X1: Risk Level | Y1: Priority | Z1: Next Action | AA1: Owner | AB1: Target Date (yyyy-mm-dd) | AC1: Notes | AD1: Readiness Score (0–100)
A2: CLO001 | B2: Cloudskraal | C2: Operating | D2: Own | E2: Northern Cape | G2: Nieuwoudtville | H2: 0 | I2: 757.61 | J2: Rooibos | K2: 500 cattle | L2: River | M2: Solar | N2: Homestead, Tea Courts, Sheds | O2: Clay | P2: -33.00, 19.50 | Q2: Self | R2: Jane Smith | S2: N/A | T2: 0 | U2: 0 | V2: 20 | W2: Core | X2: Low | Y2: P1 | Z2: N/A | AA2: Bob | AB2: 46203 | AC2: Key operational farm. | AD2: 100
A3: GAR002 | B3: Garsland | C3: Operating | D3: Own | E3: Northern Cape | G3: Nieuwoudtville | H3: 1.4 | I3: 73.66 | J3: Rooibos | K3: 20 tons | L3: Borehole | M3: Solar | N3: Homestead, Sheds, Dams | O3: Sandy Loam | P3: -33.34, 19.33 | Q3: AgriCo | R3: John Doe | S3: Term Sheet | T3: 500000 | U3: 100000 | V3: 15 | W3: Core | X3: Med | Y3: P1 | Z3: Due Diligence | AA3: Alice | AB3: 46022 | AC3: Initial assessment looks good. | AD3: 80
A4: GLE003 | B4: Glenridge Leeus | C4: Operating | D4: Own | E4: Northern Cape | G4: Nieuwoudtville | H4: 3.4 | I4: 390.82 | J4: Rooibos | K4: 300 tons | L4: Borehole | M4: Solar | N4: Cellar | O4: Granite | P4: -33.45, 18.67 | Q4: Self | R4: Eva Brown | S4: N/A | T4: 0 | U4: 0 | V4: 22 | W4: Core | X4: Low | Y4: P1 | Z4: Harvest Prep | AA4: Alice | AB4: 45962 | AC4: Stable production. | AD4: 100
A5: GLE004 | B5: Glenridge Kerk | C5: Operating | D5: Own | E5: Northern Cape | G5: Nieuwoudtville | H5: 5.1 | I5: 292.81 | J5: Livestock | M5: Solar
A6: BIE005 | B6: Biekoes - Vaal | C6: Operating | D6: Own | E6: Northern Cape | G6: Nieuwoudtville | H6: 0.3 | I6: 622.7 | J6: Rooibos | K6: 1000 tons | L6: Dam | M6: Solar | N6: Silo | O6: Loam | P6: -32.30, 20.00 | Q6: Farmer X | R6: Chris Green | S6: LOI | T6: 1000000 | U6: 200000 | V6: 18 | W6: Adjacent | X6: Med | Y6: P2 | Z6: Finalize Agreement | AA6: David | AB6: 46096 | AC6: Good potential for expansion. | AD6: 60
A7: BIE006 | B7: Biekoes - Straatklip | C7: Operating | D7: Own | E7: Northern Cape | F7: 5/645 | G7: Nieuwoudtville | H7: 1.8 | I7: 169.42 | J7: Rooibos | M7: Solar
A8: KAR007 | B8: Karoo - Winterplaas CL | C8: Operating | D8: Own | E8: Western Cape | F8: RE/224 | G8: Nieuwoudtville | H8: 4.3 | I8: 2872.19 | J8: Livestock | K8: 400 Sheep | L8: Borehole | M8: None | N8: Kraal | O8: Rocky | P8: -33.90, 21.00 | Q8: Farmer Y | R8: Frank White | S8: MOU | T8: 750000 | U8: 150000 | V8: 17 | W8: Adjacent | X8: Med | Y8: P2 | Z8: Valuation | AA8: Bob | AB8: 46053 | AC8: Requires infrastructure upgrade. | AD8: 50
A9: KAR008 | B9: Karoo CL Kromvlei | C9: Operating | D9: Own | E9: Western Cape | F9: 1/224 | G9: Nieuwoudtville | H9: 3.8 | I9: 1173.2 | J9: Livestock | K9: 200 Sheep | M9: None
A10: CLA009 | B10: Claudskraal 645 (6/7/8/9) | C10: Prospective | D10: Occupation | E10: Northern Cape | G10: Nieuwoudtville | H10: 0.1 | I10: 295.5 | J10: Rooibos | M10: Eskom
A11: KLI010 | B11: Klippe Rivier 645/(19/18/6) | C11: Prospective | D11: Occupation | E11: Northern Cape | G11: Nieuwoudtville | H11: 3 | I11: 267.51 | J11: Livestock | M11: Eskom
A12: KRO011 | B12: Kromvlei | C12: Prospective | D12: Negotiating | E12: Northern Cape | F12: RE/644 | G12: Nieuwoudtville | H12: 2.8 | I12: 391.02 | J12: Rooibos | M12: Eskom
A13: KRO012 | B13: Kromvlei Driehoek | C13: Prospective | D13: Negotiating | E13: Northern Cape | F13: RE/637 | G13: Nieuwoudtville | H13: 4.3 | I13: 199.16 | J13: Rooibos | M13: Eskom
A14: TAB013 | B14: Tabaktuin | C14: Prospective | D14: No Offer | E14: Northern Cape | G14: Nieuwoudtville | H14: 4.7 | J14: Rooibos | M14: Eskom

Sheet Fields
A1: Field Name / Identifier | B1: Farm Name (Linked) | C1: Field ID | D1: Title Deed / Notes | E1: Size (ha) | F1: Perimeter (m) | G1: Crop / Enterprise | H1: Current Status | I1: Planting Date (yyyy-mm-dd) | J1: Harvest Date (yyyy-mm-dd) | K1: Yield Target (kg or t/ha) | L1: Soil Type | M1: Irrigation Type | N1: Water Source | O1: Fertility / Input Notes | P1: Weed / Pest Pressure | Q1: Risk Level | R1: Last Activity | S1: Next Action | T1: Responsible Person | U1: GPS / Shape ID | V1: Notes | W1: % of Farm Area
A2: Rooibos-1 | B2: Garsland | C2: F001 | D2: Block R1 | E2: 25 | F2: 2000 | G2: Rooibos | H2: Planted | I2: 45726 | J2: 46068 | K2: 800 kg/ha | L2: Sand | M2: Drip | N2: Borehole | O2: Fertiliser Mix A | P2: Low | Q2: Low | R2: Sprayed 2025-09-20 | S2: Apply Herbicide | T2: Alice | U2: [URL] | V2: Good growth. | W2: 34
A3: Block A | B3: Cloudskraal | C3: F002 | D3: Camp 1 | E3: 150 | F3: 5500 | G3: Grazing | H3: Pasture | I3: N/A | J3: N/A | K3: 100 cattle | L3: Clay | M3: None | N3: River | O3: Pasture rotation plan | P3: Low | Q3: Low | R3: Checked 2025-09-28 | S3: Move livestock | T3: Bob | U3: [URL] | V3: Needs reseeding. | W3: 19.8
A4: Vineyard-West | B4: Glenridge | C4: F003 | D4: Vineyard Block 3 | E4: 15 | F4: 1200 | G4: Vines | H4: Planted | I4: 45139 | J4: 46082 | K4: 10 t/ha | L4: Loam | M4: Drip | N4: Eskom | O4: Organic compost | P4: Medium | Q4: Medium | R4: Pruned 2025-09-15 | S4: Apply Fungicide | T4: Eva | U4: [URL] | V4: Healthy vines. | W4: 3.8
A5: Block B | B5: Biekoes | C5: F004 | D5: Field B | E5: 100 | F5: 4000 | G5: Wheat | H5: Planted | I5: 45778 | J5: 45981 | K5: 5 t/ha | L5: Loam | M5: Pivot | N5: Dam | O5: Standard fertilising | P5: Medium | Q5: Medium | R5: Sprayed 2025-09-25 | S5: Harvest | T5: David | U5: [URL] | V5: Anticipating good yield. | W5: 16
A6: Old Lands | B6: Kromvlei 244 | C6: F005 | D6: Historical Area | E6: 50 | F6: 3000 | G6: Fallow | H6: Fallow | I6: N/A | J6: N/A | K6: N/A | L6: Sandy | M6: None | N6: Rainfed | O6: Cover crop planned | P6: High | Q6: High | R6: Ploughed 2025-08-10 | S6: Plant Cover Crop | T6: Bob | U6: [URL] | V6: Rest period. | W6: 20
A7: Rooibos-2 | B7: Garsland | C7: F006 | D7: Block R2 | E7: 10 | F7: 1000 | G7: Rooibos | H7: Planned | I7: 46082 | J7: 46419 | K7: 750 kg/ha | L7: Sand | M7: Drip | N7: Borehole | O7: Soil test needed | P7: Low | Q7: Low | R7: Soil Sample 2025-09-01 | S7: Prepare soil | T7: Alice | U7: [URL] | V7: Future expansion. | W7: 13.6
A8: North Pasture | B8: Cloudskraal | C8: F007 | D8: Camp 2 | E8: 200 | F8: 6500 | G8: Grazing | H8: Pasture | I8: N/A | J8: N/A | K8: 150 cattle | L8: Clay | M8: None | N8: River | O8: Winter feed | P8: Low | Q8: Low | R8: Rotated 2025-09-20 | S8: Check fences | T8: Bob | U8: [URL] | V8: Regular use. | W8: 26.4
A9: Vineyard-East | B9: Glenridge | C9: F008 | D9: Vineyard Block 1 | E9: 20 | F9: 1500 | G9: Vines | H9: Harvested | I9: 45488 | J9: 45721 | K9: 12 t/ha | L9: Granite | M9: Drip | N9: Eskom | O9: Post-harvest nutrients | P9: Low | Q9: Low | R9: Fertilized 2025-04-10 | S9: Winter Pruning | T9: Eva | U9: [URL] | V9: Excellent quality. | W9: 5.1
A10: Lucerne Patch | B10: Biekoes | C10: F009 | D10: Small Section | E10: 20 | F10: 800 | G10: Lucerne | H10: Planted | I10: 45323 | J10: 45950 | K10: 5 t/ha | L10: Clay | M10: Flood | N10: Dam | O10: Dolomitic lime | P10: Low | Q10: Medium | R10: Irrigated 2025-09-29 | S10: Harvest | T10: David | U10: [URL] | V10: Good for livestock feed. | W10: 3.2
A11: Riverbank Fields | B11: Garsland | C11: F010 | D11: Adjacent to River | E11: 15 | F11: 1500 | G11: Other | H11: Fallow | I11: N/A | J11: N/A | K11: N/A | L11: Mixed | M11: None | N11: River | O11: Erosion control needed | P11: Medium | Q11: Medium | R11: Analysed 2025-07-01 | S11: Erosion control | T11: Alice | U11: [URL] | V11: Environmental focus. | W11: 20.4

Sheet Workers

Sheet Suppliers
A1: Supplier Name | B1: Legal Entity | C1: VAT Number | D1: B-BBEE Level | E1: Registration / CSD No | F1: Primary Contact | G1: Phone | H1: Email | I1: Website | J1: Physical Address | K1: Delivery Regions | L1: Product Categories | M1: Payment Terms | N1: Preferred Supplier | O1: Incoterms / Delivery | P1: Minimum Order Qty / Value | Q1: Lead Time (days) | R1: Lead Time Variability | S1: Return Policy Summary | T1: Certifications | U1: SDS/MSDS Link | V1: Notes | W1: Reliability Score
A2: AgriSuppliers | B2: Pty Ltd | C2: 4001234567 | D2: Level 2 | E2: CSD2022-001 | F2: John Farmer | G2: +27211234567 | H2: info@agrisuppliers.co.za | I2: [URL] | J2: 123 Farm Rd, Cape Town | K2: WC, EC, NC | L2: Fertiliser, Seed, Pesticide, Herbicide, Fuel | M2: 30d EOM | N2: TRUE | O2: Delivered | P2: R 5,000 | Q2: 7 | R2: Low | S2: 30-day return for unopened products | T2: SANS, ISO 9001 | U2: [URL] | V2: Excellent service, competitive pricing | W2: 90
A3: CropCare Solutions | B3: Pty Ltd | C3: 4009876543 | D3: Level 4 | E3: CSD2022-002 | F3: Sarah Green | G3: +27217654321 | H3: sales@cropcare.co.za | I3: [URL] | J3: 45 Industry St, Bellville | K3: WC, EC | L3: Pesticide, Fungicide, Herbicide, PPE | M3: 15d | N3: TRUE | O3: Delivered | P3: R 2,000 | Q3: 10 | R3: Medium | S3: Standard 14-day return | T3: GAP Certified | U3: [URL] | V3: Specializes in organic solutions | W3: 80
A4: AgroChem | B4: CC | C4: 4005558888 | D4: Level 3 | E4: CSD2022-003 | F4: Peter Pest | G4: +27218889999 | H4: orders@agrochem.com | I4: [URL] | J4: 78 Warehouse Ave, Paarl | K4: WC | L4: Herbicide, Pesticide, Fungicide | M4: COD | N4: FALSE | O4: Ex-works | P4: R 1,000 | Q4: 5 | R4: Low | S4: No returns on opened chemicals | T4: SDS/MSDS available | U4: [URL] | V4: Good for urgent orders | W4: 45
A5: SeedMasters | B5: Pty Ltd | C5: 4001112222 | D5: Level 1 | E5: CSD2022-004 | F5: Lisa Plant | G5: +27213334444 | H5: hello@seedmasters.co.za | I5: [URL] | J5: 90 Seed Ln, Malmesbury | K5: National | L5: Seed | M5: 30d EOM | N5: TRUE | O5: Delivered | P5: R 10,000 | Q5: 14 | R5: Medium | S5: Returns only for quality defects | T5: Organic Certified, SANS | U5: [URL] | V5: Wide variety of specialized seeds | W5: 75
A6: WaterWorks | B6: Pty Ltd | C6: 4007771111 | D6: Level 5 | E6: CSD2022-005 | F6: Mark Stream | G6: +27216667777 | H6: support@waterworks.net | I6: [URL] | J6: 10 Pump Rd, Stellenbosch | K6: WC | L6: Irrigation | M6: 60d | N6: TRUE | O6: Delivered | P6: R 3,000 | Q6: 20 | R6: High | S6: 7-day return on faulty parts | T6: ISO 14001 | U6: [URL] | V6: Reliable irrigation system supplier | W6: 65
A7: PetroFuel | B7: Pty Ltd | C7: 4002223333 | D7: Level 8 | E7: N/A | F7: Nomusa Diesel | G7: +27215556666 | H7: fuel@petrofuel.co.za | I7: [URL] | J7: 50 Tanker Way, Atlantis | K7: WC, EC | L7: Fuel | M7: COD | N7: FALSE | O7: Delivered | P7: 500 L | Q7: 3 | R7: Low | S7: No returns on fuel | T7: N/A | U7: [URL] | V7: Bulk fuel delivery | W7: 30
A8: LabServices | B8: Sole Prop | C8: N/A | D8: Level 6 | E8: N/A | F8: Dr. Ana Test | G8: +27214445555 | H8: lab@labservices.co.za | I8: [URL] | J8: 20 Science Park, Somerset West | K8: WC | L8: Lab | M8: 15d | N8: FALSE | O8: Delivered | P8: R 500 | Q8: 10 | R8: Low | S8: N/A | T8: ISO 17025 | U8: [URL] | V8: Soil and water testing | W8: 65
A9: FarmTools | B9: Pty Ltd | C9: 4003334444 | D9: Level 2 | E9: CSD2022-006 | F9: Sipho Gear | G9: +27219990000 | H9: sales@farmtools.co.za | I9: [URL] | J9: 11 Tractor St, Wellington | K9: WC, NC | L9: PPE, Other (Farm Equipment Parts) | M9: 30d EOM | N9: TRUE | O9: Delivered | P9: R 1,500 | Q9: 12 | R9: Medium | S9: 30-day exchange for defective items | T9: SANS | U9: [URL] | V9: Good for specialized tools | W9: 75

Sheet Customer
A1: Customer Name | B1: Business Type | C1: Legal Entity | D1: VAT Number | E1: Registration No / Importer No | F1: Primary Contact | G1: Phone | H1: Email | I1: Website | J1: Physical Address | K1: Delivery Region / Market | L1: Preferred Products | M1: Contract Type | N1: Contract Volume (annual or per cycle, with units) | O1: Contract Price (R/unit) | P1: Current Order Pipeline (live quantity ordered, R value) | Q1: Payment Terms | R1: Payment Status | S1: Logistics / Delivery Terms | T1: Certifications Required | U1: Notes | V1: Reliability Score
A2: Tea Exporters | B2: Exporter | C2: Pty Ltd | D2: 4001112222 | E2: EXP-2025-001 | F2: Emily Green | G2: +27211234567 | H2: orders@teaexporters.com | I2: [URL] | J2: 10 Port Rd, Cape Town | K2: Export | L2: Rooibos | M2: Annual | N2: 50,000 kg | O2: 45 | P2: 10,000 kg, R450,000 | Q2: 30d EOM | R2: Good | S2: Delivered | T2: Organic, Export Clearance | U2: Long-standing export partner | V2: 90
A3: Local Winery | B3: Processor | C3: Pty Ltd | D3: 4003334444 | E3: N/A | F3: David Grape | G3: +27219876543 | H3: procurement@localwinery.co.za | I3: [URL] | J3: 20 Vine Rd, Stellenbosch | K3: Local | L3: Grapes, Wine | M3: Seasonal | N3: 100,000 kg (grapes) | O3: 12.5 | P3: 20,000 kg, R250,000 | Q3: 30 days | R3: Pending | S3: Ex-Farm | T3: HACCP | U3: Primary grape buyer | V3: 65
A4: Flour Mill | B4: Processor | C4: Pty Ltd | D4: 4005556666 | E4: N/A | F4: Sarah Grain | G4: +27212345678 | H4: purchase@flourmill.com | I4: [URL] | J4: 30 Silo Ave, Malmesbury | K4: National | L4: Grains | M4: Offtake | N4: 15,000 t (wheat) | O4: 3500 | P4: 5,000 t, R17,500,000 | Q4: 60d | R4: Good | S4: Shared Transport | T4: None | U4: Reliable bulk grain purchaser | V4: 80
A5: Butcher Shop | B5: Retailer | C5: Sole Prop | D5: N/A | E5: N/A | F5: Sipho Meat | G5: +27218765432 | H5: orders@butchershop.co.za | I5: [URL] | J5: 40 High St, Paarl | K5: Local | L5: Livestock | M5: Spot | N5: N/A | O5: 2500 | P5: 10 head, R25,000 | Q5: COD | R5: Good | S5: Delivered | T5: None | U5: Buys smaller, fresh batches | V5: 30
A6: Textile Factory | B6: Processor | C6: Pty Ltd | D6: 4007778888 | E6: EXP-2025-002 | F6: Lena Wool | G6: +27213456789 | H6: sales@textilefactory.co.za | I6: [URL] | J6: 50 Fabric Ln, Atlantis | K6: Export | L6: Wool | M6: Annual | N6: 200 bales | O6: 800 | P6: 50 bales, R40,000 | Q6: 60d EOM | R6: Pending | S6: Delivered | T6: Fairtrade, Export Clearance | U6: Seeking sustainable wool sources | V6: 80
A7: Supermarket Chain | B7: Retailer | C7: Pty Ltd | D7: 4009990000 | E7: N/A | F7: Ben Fresh | G7: +27214567890 | H7: freshproduce@superchain.com | I7: [URL] | J7: 60 Market Sq, Worcester | K7: National | L7: Vegetables, Fruit | M7: Seasonal | N7: 5,000 kg (tomatoes) | O7: 18 | P7: 1,000 kg, R18,000 | Q7: 30 days | R7: Good | S7: Delivered | T7: HACCP, Organic | U7: Keen on organic produce | V7: 70
A8: Fruit Wholesaler | B8: Wholesaler | C8: Pty Ltd | D8: 4001213141 | E8: N/A | F8: Chris Fruit | G8: +27215678901 | H8: info@fruitwholesaler.com | I8: [URL] | J8: 70 Orchard Rd, Grabouw | K8: Local | L8: Fruit | M8: Spot | N8: N/A | O8: 15 | P8: 500 kg, R7,500 | Q8: 30 days | R8: Late | S8: Ex-Farm | T8: HACCP | U8: Sometimes slow with payments | V8: 45
A9: Compost Solutions | B9: Other (Processor) | C9: Pty Ltd | D9: 4001516171 | E9: N/A | F9: Anna Waste | G9: +27216789012 | H9: sales@compostsolutions.co.za | I9: [URL] | J9: 80 Green Way, Strand | K9: Local | L9: By-products | M9: Seasonal | N9: 2,000 kg (grape pomace) | O9: 2.5 | P9: 500 kg, R1,250 | Q9: COD | R9: Good | S9: Ex-Farm | T9: None | U9: Buys farm waste for compost | V9: 40
A10: Brew Masters | B10: Processor | C10: Pty Ltd | D10: 4001819202 | E10: N/A | F10: Mark Malt | G10: +27217890123 | H10: malt@brewmasters.co.za | I10: [URL] | J10: 90 Brewery St, George | K10: National | L10: Grains (Barley) | M10: Annual | N10: 7,000 t (barley) | O10: 4000 | P10: 1,500 t, R6,000,000 | Q10: 60 days | R10: Good | S10: Delivered | T10: None | U10: Key supplier for malt barley | V10: 75
A11: Local Market Stalls | B11: Direct Consumer | C11: Sole Prop | D11: N/A | E11: N/A | F11: Zola Vendor | G11: +27210123456 | H11: zola@marketstalls.co.za | I11: [URL] | J11: 100 Town Sq, Franschhoek | K11: Local | L11: Vegetables, Fruit, Other | M11: Spot | N11: N/A | O11: 150 | P11: 10 units, R1,500 | Q11: COD | R11: Good | S11: Ex-Farm | T11: None | U11: Regular small quantity buyer | V11: 30

Sheet Outputs
A1: Output ID | B1: Date | C1: Farm Name | D1: Field Name | E1: Output Category | F1: Product Name | G1: Variety / Breed | H1: Quantity | I1: Unit | J1: Quality Grade | K1: Buyer / Customer | L1: Destination / Market | M1: Price per Unit (R) | N1: Total Value | O1: Invoice / Delivery Note Ref | P1: Certification | Q1: Logistics Partner | R1: Storage Location | S1: Costs Allocated (R) | T1: Net Margin (R) | U1: Payment Terms | V1: Payment Status | W1: Responsible Person | X1: Notes
A2: OUT-001 | B2: 45928 | C2: Green Acres | D2: North Field | E2: Rooibos | F2: Rooibos Grade A | G2: Superior Blend | H2: 5000 | I2: kg | J2: Export | K2: Tea Exporters | L2: Export | M2: 45 | N2: 225000 | O2: INV-RA-001 | P2: Organic | Q2: Global Freight | R2: Warehouse | S2: 100000 | T2: 125000 | U2: 30 days | V2: Paid | W2: John Doe | X2: Shipped to Germany
A3: OUT-002 | B3: 45925 | C3: Sunny Fields | D3: East Meadow | E3: Grapes/Wine | F3: Chenin Blanc grapes | G3: Chenin Blanc | H3: 8000 | I3: kg | J3: A | K3: Local Winery | L3: Processor | M3: 12.5 | N3: 100000 | O3: DN-CB-002 | P3: GAP | Q3: Own Transport | R3: Winery Cellar | S3: 40000 | T3: 60000 | U3: 30 days | V3: Pending | W3: Jane Smith | X3: Harvested at optimal ripeness
A4: OUT-003 | B4: 45920 | C4: Harvest Valley | D4: Central Plot | E4: Grain | F4: Wheat Grade B | G4: Southern Star | H4: 15000 | I4: t | J4: B | K4: Flour Mill | L4: Coop | M4: 3500 | N4: 52500000 | O4: INV-WG-003 | P4: None | Q4: Rail Logistics | R4: Silo | S4: 20000000 | T4: 32500000 | U4: 60 days | V4: Paid | W4: Peter Jones | X4: Bulk delivery completed
A5: OUT-004 | B5: 45918 | C5: Green Acres | D5: South Field | E5: Livestock | F5: Dorper Lamb | G5: Dorper | H5: 50 | I5: head | J5: A | K5: Butcher Shop | L5: Local | M5: 2500 | N5: 125000 | O5: DN-DL-004 | P5: None | Q5: Local Courier | R5: Cold Room | S5: 50000 | T5: 75000 | U5: COD | V5: Paid | W5: Sarah Lee | X5: Delivered fresh to market
A6: OUT-005 | B6: 45915 | C6: Sunny Fields | D6: West Pasture | E6: Wool | F6: Merino Wool Fine | G6: Merino | H6: 200 | I6: bales | J6: Export | K6: Textile Factory | L6: Export | M6: 800 | N6: 160000 | O6: INV-MW-005 | P6: Fairtrade | Q6: Ocean Cargo | R6: Warehouse | S6: 70000 | T6: 90000 | U6: 60 days | V6: Pending | W6: David Kim | X6: Sheared this season
A7: OUT-006 | B7: 45910 | C7: Harvest Valley | D7: River Bend | E7: Vegetables | F7: Tomatoes | G7: Roma | H7: 1000 | I7: kg | J7: A | K7: Supermarket | L7: Direct-to-Consumer | M7: 18 | N7: 18000 | O7: DN-TM-006 | P7: Organic | Q7: Own Transport | R7: N/A | S7: 8000 | T7: 10000 | U7: 30 days | V7: Paid | W7: Emily White | X7: Freshly picked for local stores
A8: OUT-007 | B8: 45905 | C8: Green Acres | D8: North Field | E8: Fruit | F8: Apples | G8: Granny Smith | H8: 3000 | I8: kg | J8: B | K8: Fruit Wholesaler | L8: Local | M8: 15 | N8: 45000 | O8: INV-AP-007 | P8: HACCP | Q8: Cold Chain Trans | R8: Cold Room | S8: 15000 | T8: 30000 | U8: 30 days | V8: Overdue | W8: John Doe | X8: Delayed payment expected
A9: OUT-008 | B9: 45901 | C9: Sunny Fields | D9: East Meadow | E9: By-products | F9: Grape Pomace | G9: Chenin Blanc | H9: 2000 | I9: kg | J9: C | K9: Compost Co | L9: Processor | M9: 2.5 | N9: 5000 | O9: DN-GP-008 | P9: None | Q9: Own Transport | R9: Compost Pile | S9: 1000 | T9: 4000 | U9: COD | V9: Paid | W9: Jane Smith | X9: Residue from wine production
A10: OUT-009 | B10: 45897 | C10: Harvest Valley | D10: Central Plot | E10: Grain | F10: Barley | G10: Malt Grade | H10: 7000 | I10: t | J10: A | K10: Brewery | L10: Coop | M10: 4000 | N10: 28000000 | O10: INV-BL-009 | P10: GAP | Q10: Road Haulers | R10: Silo | S10: 12000000 | T10: 16000000 | U10: 60 days | V10: Pending | W10: Peter Jones | X10: Used for brewing
A11: OUT-010 | B11: 45889 | C11: Green Acres | D11: South Field | E11: Other | F11: Firewood | G11: Eucalyptus | H11: 100 | I11: units | J11: C | K11: Local Market | L11: Direct-to-Consumer | M11: 150 | N11: 15000 | O11: DN-FW-010 | P11: None | Q11: Own Transport | R11: Wood Shed | S11: 5000 | T11: 10000 | U11: COD | V11: Paid | W11: Sarah Lee | X11: Collected from farm maintenance

Sheet Inputs
A1: Input ID | B1: Date Applied | C1: Farm Name | D1: Field Name | E1: Input Category | F1: Input Name / Product | G1: Supplier | H1: Batch / Invoice # | I1: Application Rate (per ha or per litre) | J1: Total Quantity Used | K1: Unit | L1: Application Method | M1: Purpose | N1: Labour Hrs | O1: Cost per Unit (R) | P1: Total Cost | Q1: Responsible Person | R1: Next Action / Follow-up | S1: Notes
A2: FI-001 | B2: 45915 | C2: Green Acres | D2: North Field | E2: Fertiliser | F2: Urea 46% | G2: AgriSuppliers | H2: INV-2025-001 | I2: 150 kg/ha | J2: 1500 | K2: kg | L2: Broadcast | M2: Fertility boost | N2: 4 | O2: 8.5 | P2: 12750 | Q2: John Doe | R2: Reapply in 6 months | S2: Post-harvest application
A3: FI-002 | B3: 45910 | C3: Sunny Fields | D3: East Meadow | E3: Pesticide | F3: Prosper 250 EC | G3: CropCare Solutions | H3: BAT-P250-003 | I3: 1.5 L/ha | J3: 30 | K3: L | L3: Spray | M3: Pest control | N3: 6 | O3: 350 | P3: 10500 | Q3: Jane Smith | R3: Monitor pest levels weekly | S3: Applied after initial pest sighting
A4: FI-003 | B4: 45897 | C4: Harvest Valley | D4: Central Plot | E4: Herbicide | F4: Glyphosate Ultra | G4: AgroChem | H4: INV-2025-002 | I4: 2 L/ha | J4: 80 | K4: L | L4: Spray | M4: Weed control | N4: 5 | O4: 220 | P4: 17600 | Q4: Peter Jones | R4: Apply pre-emergence next season | S4: Effective on broadleaf weeds
A5: FI-004 | B5: 45920 | C5: Green Acres | D5: South Field | E5: Seed | F5: Hybrid Maize C12 | G5: SeedMasters | H5: BAT-HMC-001 | I5: 8 kg/ha | J5: 80 | K5: packs | L5: Manual | M5: Crop establishment | N5: 10 | O5: 1200 | P5: 96000 | Q5: Sarah Lee | R5: Check germination in 14 days | S5: Planted during optimal weather
A6: FI-005 | B6: 45901 | C6: Sunny Fields | D6: West Pasture | E6: Labour | F6: Tractor Driving | G6: Farm Crew | H6: TIMESHEET-09-01 | I6: N/A | J6: 20 | K6: hrs | L6: Tractor | M6: Land preparation | N6: 20 | O6: 150 | P6: 3000 | Q6: David Kim | R6: N/A | S6: Field plowing completed
A7: FI-006 | B7: 45884 | C7: Harvest Valley | D7: River Bend | E7: Irrigation | F7: Drip System Repair | G7: WaterWorks | H7: INV-2025-003 | I7: N/A | J7: 1 | K7: hrs | L7: Drip | M7: Water management | N7: 2 | O7: 500 | P7: 1000 | Q7: Emily White | R7: Inspect system monthly | S7: Minor leak repaired
A8: FI-007 | B8: 45925 | C8: Green Acres | D8: North Field | E8: Fungicide | F8: Azoxystrobin | G8: AgroGuard | H8: BAT-AZO-002 | I8: 0.8 L/ha | J8: 8 | K8: L | L8: Spray | M8: Disease prevention | N8: 3 | O8: 450 | P8: 3600 | Q8: John Doe | R8: Reapply in 21 days | S8: Proactive disease management
A9: FI-008 | B9: 45918 | C9: Sunny Fields | D9: East Meadow | E9: Fuel | F9: Diesel | G9: PetroFuel | H9: REC-10045 | I9: N/A | J9: 100 | K9: L | L9: Tractor | M9: Equipment operation | N9: N/A | O9: 18.5 | P9: 1850 | Q9: Jane Smith | R9: Top up tank next week | S9: Used for sprayer operations
A10: FI-009 | B10: 45899 | C10: Harvest Valley | D10: Central Plot | E10: Other | F10: Soil Sampling | G10: LabServices | H10: INV-2025-004 | I10: N/A | J10: 1 | K10: packs | L10: Manual | M10: Soil health assessment | N10: 8 | O10: 750 | P10: 750 | Q10: Peter Jones | R10: Receive lab results by 2025-10-15 | S10: Samples sent for nutrient analysis
A11: FI-010 | B11: 45912 | C11: Green Acres | D11: South Field | E11: Fertiliser | F11: Potassium Sulphate | G11: AgriSuppliers | H11: INV-2025-005 | I11: 80 kg/ha | J11: 800 | K11: kg | L11: Broadcast | M11: Nutrient supplementation | N11: 3 | O11: 12 | P11: 9600 | Q11: Sarah Lee | R11: Monitor crop response | S11: Applied before flowering

Sheet Equipment
A1: Equipment ID | B1: Farm Name | C1: Equipment Type | D1: Make | E1: Model | F1: Year | G1: Serial Number | H1: Status | I1: Last Service Date | J1: Next Service Due (Date) | K1: Condition | L1: Ownership | M1: Acquisition Date | N1: Purchase Price (R) | O1: Supplier / Dealer | P1: Warranty Expiry | Q1: Responsible Person | R1: Notes
A2: ME-001 | B2: Green Acres | C2: Sprayer | D2: Hardi | E2: Navigator 4000 | F2: 2022 | G2: HARD-N4K-123 | H2: Active | I2: 45809 | J2: 46174 | K2: Good | L2: Own | M2: 44671 | N2: 380000 | O2: CropCare Solutions | P2: 46497 | Q2: John Doe | R2: Trailed sprayer, 4000L capacity
A3: ME-002 | B3: Sunny Fields | C3: Cultivator | D3: Vaderstad | E3: Carrier 420 | F3: 2023 | G3: VAD-C420-456 | H3: Active | I3: N/A | J3: N/A | K3: Excellent | L3: Own | M3: 45179 | N3: 250000 | O3: AgriSuppliers | P3: 47006 | Q3: Jane Smith | R3: Flexible stubble cultivator
A4: ME-003 | B4: Harvest Valley | C4: Baler | D4: Krone | E4: Comprima V150 | F4: 2021 | G4: KRO-CV150-789 | H4: In Repair | I4: 45853 | J4: 46218 | K4: Needs Repair | L4: Own | M4: 44260 | N4: 420000 | O4: FarmEquipment Co | P4: 46086 | Q4: Peter Jones | R4: Round baler, minor gearbox issue
A5: ME-004 | B5: Green Acres | C5: Generator | D5: Cummins | E5: C110D5 | F5: 2019 | G5: CUM-C110D5-012 | H5: Standby | I5: 45672 | J5: 46037 | K5: Good | L5: Own | M5: 43748 | N5: 220000 | O5: Generator World | P5: N/A | Q5: Sarah Lee | R5: Emergency power backup for packing shed
A6: ME-005 | B6: Sunny Fields | C6: Pump | D6: Grundfos | E6: SP 17-10 | F6: 2020 | G6: GF-SP17-10-345 | H6: Active | I6: 45736 | J6: 46101 | K6: Good | L6: Own | M6: 44044 | N6: 60000 | O6: WaterWorks | P6: 45870 | Q6: David Kim | R6: Borehole pump, due for replacement
A7: ME-006 | B7: Harvest Valley | C7: Harvester | D7: Claas | E7: Lexion 760 | F7: 2024 | G7: CLA-L760-678 | H7: Active | I7: N/A | J7: 46113 | K7: Excellent | L7: Lease | M7: 45383 | N7: 3500000 | O7: Premium Harvesters | P7: 47209 | Q7: Emily White | R7: New lease, high capacity combine
A8: ME-007 | B8: Green Acres | C8: Disc Harrow | D8: Lemken | E8: Heliodor 9 | F8: 2022 | G8: LEM-H9-901 | H8: Active | I8: N/A | J8: N/A | K8: Excellent | L8: Own | M8: 44880 | N8: 180000 | O8: AgriSuppliers | P8: 46706 | Q8: John Doe | R8: Used for seedbed preparation
A9: ME-008 | B9: Sunny Fields | C9: Loader | D9: Caterpillar | E9: 906M | F9: 2020 | G9: CAT-906M-234 | H9: Active | I9: 45752 | J9: 46117 | K9: Good | L9: Own | M9: 44022 | N9: 700000 | O9: EarthMoving Solutions | P9: N/A | Q9: Jane Smith | R9: Versatile for material handling
A10: ME-009 | B10: Harvest Valley | C10: Shredder | D10: Fecon | E10: FTX100 | F10: 2023 | G10: FEC-FTX100-567 | H10: Active | I10: 45901 | J10: 46266 | K10: Good | L10: Own | M10: 44946 | N10: 320000 | O10: Forestry Equipment | P10: 46772 | Q10: Peter Jones | R10: Used for clearing brush and pruning
A11: ME-010 | B11: Green Acres | C11: Planter | D11: Amazone | E11: Citan 12001-C | F11: 2024 | G11: AMZ-C12001-890 | H11: Active | I11: N/A | J11: N/A | K11: Excellent | L11: Own | M11: 45332 | N11: 550000 | O11: AgriSuppliers | P11: 47159 | Q11: Sarah Lee | R11: Precision seed drill for grains

Sheet Equipment 2
A1: Asset ID | B1: Asset Type | C1: Make | D1: Model | E1: Year | F1: Serial/VIN | G1: Registration/Plate | H1: Farm Name | I1: Location / Field | J1: Status | K1: Owner/Lease | L1: Acquisition Date | M1: Supplier / Dealer | N1: Purchase Price (R) | O1: Est. Current Value (R) | P1: Depreciation Method | Q1: Useful Life (years) | R1: Meter Type | S1: Current Meter Reading | T1: Last Service Date | U1: Last Service Meter | V1: Service Interval (Hours) | W1: Next Service Due (Hours) | X1: Next Service Date | Y1: Fuel Type | Z1: Avg Fuel Use (L/hr or L/100km) | AA1: Tyre Size / Count | AB1: Implement Width (m) | AC1: PTO/Power (kW/HP) | AD1: Hydraulic/Notes | AE1: Service Provider | AF1: Warranty Expiry | AG1: Insurance Policy # | AH1: Documents | AI1: Condition | AJ1: Criticality | AK1: Downtime (hrs YTD) | AL1: Opex YTD (R) | AM1: Capex YTD (R) | AN1: Notes
A2: EQ-001 | B2: Tractor | C2: John Deere | D2: 6120M | E2: 2023 | F2: JD6120M-S1234 | G2: CA123-456 | H2: Green Acres | I2: North Field | J2: Active | K2: Own | L2: 45000 | M2: AgriSuppliers | N2: 1200000 | O2: 1080000 | P2: Straight | Q2: 10 | R2: Hours | S2: 1550 | T2: 45787 | U2: 1000 | V2: 500 | W2: 1500 | X2: 45971 | Y2: Diesel | Z2: 12 L/hr | AA2: 460/85R38 / 4 | AB2: N/A | AC2: 90 kW / 120 HP | AD2: Standard 3-point hitch, 2 SCV | AE2: FarmMechanics | AF2: 46096 | AG2: INS-JD-001 | AH2: [URL] | AI2: Good | AJ2: High | AK2: 20 | AL2: 25000 | AM2: 0 | AN2: Main workhorse tractor for crop cultivation
A3: EQ-002 | B3: Implement | C3: Kverneland | D3: 5-furrow Plough | E3: 2022 | F3: KV-PLOUGH-5-XYZ | G3: N/A | H3: Sunny Fields | I3: East Meadow | J3: Active | K3: Own | L3: 44774 | M3: AgriSuppliers | N3: 150000 | O3: 120000 | P3: Straight | Q3: 15 | R3: none | S3: N/A | T3: N/A | U3: N/A | V3: N/A | W3: N/A | X3: N/A | Y3: N/A | Z3: N/A | AA3: N/A | AB3: 2.5 | AC3: N/A | AD3: Reversible plough for primary tillage | AE3: FarmMechanics | AF3: 46600 | AG3: INS-KV-002 | AH3: [URL] | AI3: Excellent | AJ3: Medium | AK3: 5 | AL3: 5000 | AM3: 0 | AN3: Used for primary tillage
A4: EQ-003 | B4: Vehicle | C4: Toyota | D4: Hilux 2.8 GD-6 | E4: 2024 | F4: VIN-HILUX-ABC | G4: CK111-222 | H4: Harvest Valley | I4: N/A | J4: Active | K4: Own | L4: 45311 | M4: Toyota Dealership | N4: 650000 | O4: 600000 | P4: Straight | Q4: 8 | R4: km | S4: 25000 | T4: 45839 | U4: 20000 | V4: 10000 | W4: 30000 | X4: 46023 | Y4: Diesel | Z4: 8 L/100km | AA4: 265/65R17 / 4 | AB4: N/A | AC4: N/A | AD4: Farm supervisor vehicle, off-road capable | AE4: Toyota Service | AF4: 46407 | AG4: INS-HIL-003 | AH4: [URL] | AI4: Good | AJ4: High | AK4: 10 | AL4: 12000 | AM4: 0 | AN4: Essential for farm logistics and supervision
A5: EQ-004 | B5: Pump | C5: Grundfos | D5: CR15-5 | E5: 2021 | F5: GF-CR15-5-123 | G5: N/A | H5: Green Acres | I5: Dam A | J5: In Repair | K5: Own | L5: 44505 | M5: WaterWorks | N5: 45000 | O5: 20000 | P5: Straight | Q5: 12 | R5: Hours | S5: 8500 | T5: 45580 | U5: 8000 | V5: 1000 | W5: 9000 | X5: 45945 | Y5: Electric | Z5: N/A | AA5: N/A | AB5: N/A | AC5: 7.5 kW | AD5: Centrifugal pump, currently awaiting parts | AE5: WaterWorks | AF5: 46331 | AG5: INS-GF-004 | AH5: [URL] | AI5: Needs Repair | AJ5: Critical | AK5: 120 | AL5: 8000 | AM5: 0 | AN5: Main irrigation pump, urgent repair needed
A6: EQ-005 | B6: Pivot | C6: Valley | D6: 8120 | E6: 2020 | F6: VALL-8120-QWER | G6: N/A | H6: Sunny Fields | I6: Pivot 1 | J6: Active | K6: Lease | L6: 43983 | M6: Valley Dealer | N6: 750000 | O6: 500000 | P6: Straight | Q6: 20 | R6: Hours | S6: 12000 | T6: 45736 | U6: 11000 | V6: 2000 | W6: 13000 | X6: 46101 | Y6: Electric | Z6: N/A | AA6: N/A | AB6: 400 | AC6: N/A | AD6: 8-tower pivot system, covers 50 ha | AE6: Valley Service | AF6: 46022 | AG6: INS-PV-005 | AH6: [URL] | AI6: Good | AJ6: High | AK6: 30 | AL6: 18000 | AM6: 0 | AN6: Under lease agreement, essential for irrigation
A7: EQ-006 | B7: Generator | C7: Cummins | D7: C110D5 | E7: 2019 | F7: CUMM-C110D5-FGHI | G7: N/A | H7: Harvest Valley | I7: Workshop | J7: Standby | K7: Own | L7: 43748 | M7: Generator World | N7: 220000 | O7: 100000 | P7: Straight | Q7: 15 | R7: Hours | S7: 550 | T7: 45672 | U7: 500 | V7: 250 | W7: 750 | X7: 46037 | Y7: Diesel | Z7: 15 L/hr | AA7: N/A | AB7: N/A | AC7: 88 kW / 110 kVA | AD7: Emergency backup power, runs weekly test | AE7: GenTech Solutions | AF7: 45575 | AG7: INS-GEN-006 | AH7: [URL] | AI7: Good | AJ7: Medium | AK7: 5 | AL7: 3000 | AM7: 0 | AN7: Warranty expired, but well maintained
A8: EQ-007 | B8: Sprayer | C8: Hardi | D8: Navigator 4000 | E8: 2022 | F8: HARD-NAV-JKL | G8: N/A | H8: Green Acres | I8: North Field | J8: Active | K8: Own | L8: 44671 | M8: CropCare Solutions | N8: 380000 | O8: 320000 | P8: Units-of-Use | Q8: 10 | R8: Hours | S8: 800 | T8: 45809 | U8: 500 | V8: 300 | W8: 800 | X8: 45992 | Y8: N/A | Z8: N/A | AA8: N/A | AB8: 24 | AC8: N/A | AD8: Trailed sprayer, 4000L tank capacity | AE8: CropCare Solutions | AF8: 46497 | AG8: INS-HAR-007 | AH8: [URL] | AI8: Excellent | AJ8: High | AK8: 10 | AL8: 15000 | AM8: 0 | AN8: Precision spraying equipment
A9: EQ-008 | B9: Tool | C9: Bosch | D9: Angle Grinder | E9: 2024 | F9: BOSCH-AG-MNP | G9: N/A | H9: Sunny Fields | I9: Workshop | J9: Active | K9: Own | L9: 45332 | M9: FarmTools | N9: 1500 | O9: 1400 | P9: Straight | Q9: 5 | R9: none | S9: N/A | T9: N/A | U9: N/A | V9: N/A | W9: N/A | X9: N/A | Y9: Electric | Z9: N/A | AA9: N/A | AB9: N/A | AC9: N/A | AD9: Corded angle grinder, general workshop use | AE9: FarmTools | AF9: 46428 | AG9: N/A | AH9: [URL] | AI9: Good | AJ9: Low | AK9: 0 | AL9: 100 | AM9: 0 | AN9: General workshop tool
A10: EQ-009 | B10: Other | C10: Custom Build | D10: Water Trailer | E10: 2023 | F10: CUST-WT-QRS | G10: N/A | H10: Harvest Valley | I10: N/A | J10: Active | K10: Own | L10: 45108 | M10: Local Fabricator | N10: 25000 | O10: 22000 | P10: Straight | Q10: 10 | R10: none | S10: N/A | T10: N/A | U10: N/A | V10: N/A | W10: N/A | X10: N/A | Y10: N/A | Z10: N/A | AA10: N/A | AB10: N/A | AC10: N/A | AD10: 1000L water tank on trailer | AE10: N/A | AF10: N/A | AG10: INS-CBT-009 | AH10: [URL] | AI10: Good | AJ10: Medium | AK10: 0 | AL10: 500 | AM10: 0 | AN10: Used for transporting water to fields
A11: EQ-010 | B11: Tractor | C11: Massey | D11: Ferguson 5710S | E11: 2020 | F11: MF5710S-TUVW | G11: CW789-012 | H11: Green Acres | I11: South Field | J11: In Repair | K11: Own | L11: 44075 | M11: AgriSuppliers | N11: 850000 | O11: 600000 | P11: Straight | Q11: 12 | R11: Hours | S11: 4500 | T11: 45698 | U11: 4000 | V11: 500 | W11: 4500 | X11: 45879 | Y11: Diesel | Z11: 10 L/hr | AA11: 420/85R34 / 4 | AB11: N/A | AC11: 75 kW / 100 HP | AD11: Minor engine issue, awaiting inspection | AE11: FarmMechanics | AF11: 45901 | AG11: INS-MF-010 | AH11: [URL] | AI11: Needs Repair | AJ11: High | AK11: 80 | AL11: 18000 | AM11: 0 | AN11: Secondary tractor, currently not operational

Sheet Sheep Flock
A1: Farm / Paddock Name | B1: Flock ID / Name | C1: Breed / Strain | D1: Head Count | E1: Rams | F1: Ewes | G1: Lambs | H1: Avg Age (months) | I1: Avg Weight (kg) | J1: Body Condition Score (avg, 1–5) | K1: Mortality (last 30 days) | L1: Mortality Reason | M1: Health Treatments Given | N1: Vaccination Status | O1: Deworming Status | P1: Reproduction Cycle | Q1: Lambing % | R1: Weaning % | S1: Wool / Fleece Weight (kg per head) | T1: Shearing Date | U1: Feed / Supplement | V1: Grazing Area | W1: Water Source | X1: Input Costs (R/head) | Y1: Output Value (R/head) | Z1: Net Margin | AA1: Responsible Person | AB1: Notes
A2: Green Pastures | B2: Breeding Ewes | C2: Merino | D2: 450 | E2: 15 | F2: 300 | G2: 135 | H2: 48 | I2: 65 | J2: 3.5 | K2: 1 | L2: Disease | M2: Deworming, Antibiotics | N2: Up to date | O2: Due | P2: Pregnant | Q2: 1.3 | R2: 1.15 | S2: 4.8 | T2: 45884 | U2: Lucerne & Grain | V2: North Field | W2: Borehole | X2: 120 | Y2: 250 | Z2: 130 | AA2: Sarah Jones | AB2: Good health, some ewes due for deworming.
A3: River Bend | B3: Replacement Lambs | C3: Dorper | D3: 220 | E3: 0 | F3: 0 | G3: 220 | H3: 8 | I3: 35 | J3: 3 | K3: 2 | L3: Accidents | M3: Vitamin boost | N3: Up to date | O3: Up to date | P3: Weaning | Q3: 0 | R3: 0 | S3: 0 | T3: N/A | U3: Starter Pellets | V3: East Paddock | W3: River | X3: 80 | Y3: 150 | Z3: 70 | AA3: Tom Green | AB3: Growing well, preparing for breeding next year.
A4: Mountain View | B4: Rams | C4: Merino | D4: 20 | E4: 20 | F4: 0 | G4: 0 | H4: 60 | I4: 90 | J4: 4 | K4: 0 | L4: N/A | M4: Hoof trimming | N4: Up to date | O4: Up to date | P4: Not mated | Q4: 0 | R4: 0 | S4: 6.2 | T4: 45858 | U4: High Protein Pellets | V4: Small Enclosure | W4: Spring | X4: 150 | Y4: 0 | Z4: -150 | AA4: Jane Doe | AB4: Excellent condition.
A5: Sunny Hills | B5: Sale Group | C5: Dorper | D5: 180 | E5: 10 | F5: 50 | G5: 120 | H5: 10 | I5: 40 | J5: 3.2 | K5: 3 | L5: Predators | M5: None | N5: Up to date | O5: Up to date | P5: N/A | Q5: 0 | R5: 0 | S5: 0 | T5: N/A | U5: Finishing Feed | V5: Holding Pen | W5: Dam | X5: 95 | Y5: 180 | Z5: 85 | AA5: Peter Black | AB5: Ready for market next week.
A6: Green Pastures | B6: Young Ewes | C6: Dorper | D6: 150 | E6: 0 | F6: 150 | G6: 0 | H6: 24 | I6: 55 | J6: 3.7 | K6: 4 | L6: Other | M6: Multivitamin injection | N6: Due | O6: Up to date | P6: Not mated | Q6: 0 | R6: 0 | S6: 0 | T6: N/A | U6: Hay & Mineral Lick | V6: West Paddock | W6: Borehole | X6: 100 | Y6: 0 | Z6: -100 | AA6: Sarah Jones | AB6: Awaiting ram introduction.
A7: River Bend | B7: Lambing Ewes | C7: Merino | D7: 200 | E7: 5 | F7: 200 | G7: 190 | H7: 54 | I7: 70 | J7: 3.8 | K7: 3 | L7: Disease | M7: Fly strike treatment | N7: Up to date | O7: Due | P7: Lambing | Q7: 0.95 | R7: 0.8 | S7: 5 | T7: 45870 | U7: Pre-lambing Ration | V7: Nursery Field | W7: River | X7: 130 | Y7: 260 | Z7: 130 | AA7: Tom Green | AB7: Many new lambs, monitoring ewes closely.
A8: Mountain View | B8: Weaner Lambs | C8: Merino | D8: 100 | E8: 0 | F8: 0 | G8: 100 | H8: 6 | I8: 28 | J8: 2.9 | K8: 1 | L8: Accidents | M8: Coccidiostat | N8: Up to date | O8: Up to date | P8: Weaning | Q8: 0 | R8: 0 | S8: 0 | T8: N/A | U8: Lamb Grower Pellets | V8: South Field | W8: Spring | X8: 70 | Y8: 140 | Z8: 70 | AA8: Jane Doe | AB8: Recently weaned, adjusting well.
A9: Sunny Hills | B9: Old Ewes | C9: Dorper | D9: 80 | E9: 0 | F9: 80 | G9: 0 | H9: 72 | I9: 60 | J9: 3.1 | K9: 2 | L9: Disease | M9: Arthritis medication | N9: Due | O9: Due | P9: Not mated | Q9: 0 | R9: 0 | S9: 0 | T9: 45843 | U9: Maintenance Feed | V9: Old Ewe Paddock | W9: Dam | X9: 110 | Y9: 0 | Z9: -110 | AA9: Peter Black | AB9: Cull group for end of year.
A10: Green Pastures | B10: Mixed Lambs | C10: Merino/Dorper | D10: 180 | E10: 0 | F10: 0 | G10: 180 | H10: 7 | I10: 32 | J10: 3.1 | K10: 2 | L10: Predators | M10: None | N10: Up to date | O10: Up to date | P10: N/A | Q10: 0 | R10: 0 | S10: 0 | T10: N/A | U10: Mixed Pellets | V10: Mid Field | W10: Borehole | X10: 85 | Y10: 160 | Z10: 75 | AA10: Sarah Jones | AB10: Regular checks for predator activity.

Sheet Rooibos - JOHAN BRAND - Werklik
A1: PRODUKSIE DATA VAN CLOUDSKRAAL BOERDERY PER PLAAS, LAND EN GESKATTE OPBRENGS EN WERKLIKE OES IN KILOGRAMME.
A3: PLAASNAAM | B3: LANDNAAM | C3: LANDNO | D3: GEPLANT | E3: HEKTAAR | F3: 2004 WERKLIK | G3: 2005 WERKLIK | H3: 2006_WERKLIK | I3: 2007_WERKLIK | J3: 2008_WERKLIK | K3: 2009_WERKLIK | L3: 2010_WERKLIK | M3: 2011_WERKLIK | N3: 2012_WERKLIK | O3: 2013_WERKLIK | P3: 2014_WERKLIK | Q3: 2015_WERKLIK | R3: 2016_WERKLIK | S3: 2017_WERKLIK | T3: 2018_WERKLIK | U3: 2019_WERKLIK | V3: 2020_WERKLIK | W3: 2021_WERKLIK | X3: 2022_WERKLIK | Y3: 2023_WERKLIK | Z3: 2024_WERKLIK | AA3: 25_WERKLIK
A4: Biekoes | B4: Latboskamp | C4: B7 | D4: 2021 | E4: 22.958092 | F4: N.A | G4: N.A | H4: N.A | I4: N.A | J4: 0 | K4: 6000 | L4: 5000 | M4: 0 | N4: 0 | O4: 0 | P4: 0 | Q4: 0 | R4: 0 | S4: 12000 | T4: 0 | U4: 8000 | V4: 6000 | W4: 0 | X4: 0 | Y4: 4000 | Z4: 4000 | AA4: 4000
A5: Cloudskraal | B5: Pleisterbosrug | C5: C3 | D5: 2021 | E5: 31.037026 | F5: N.A | G5: N.A | H5: N.A | I5: N.A | J5: 12000 | K5: 4000 | L5: 0 | M5: 0 | N5: 0 | O5: 7000 | P5: 13000 | Q5: 10000 | R5: 0 | S5: 0 | T5: 0 | U5: 6000 | V5: 2000 | W5: 0 | X5: 0 | Y5: 12000 | Z5: 18000 | AA5: 18000
A6: Biekoes | B6: Eerste Land | C6: B1 | D6: 2022 | E6: 21.198753 | F6: N.A | G6: N.A | H6: N.A | I6: N.A | J6: 0 | K6: 0 | L6: 0 | M6: 8000 | N6: 0 | O6: 0 | P6: 0 | Q6: 0 | R6: 0 | S6: 16000 | T6: 0 | U6: 12000 | V6: 5000 | W6: 0 | X6: 0 | Y6: 0 | Z6: 6000 | AA6: 5000
A7: Biekoes | B7: Straatklip | C7: B3 | D7: 2022 | E7: 17.032996 | F7: N.A | G7: N.A | H7: N.A | I7: N.A | J7: 0 | K7: 4000 | L7: 0 | M7: 0 | N7: 0 | O7: 0 | P7: 0 | Q7: 0 | R7: 12000 | S7: 17000 | T7: 0 | U7: 5000 | V7: 0 | W7: 0 | X7: 0 | Y7: 0 | Z7: 7500 | AA7: 8000
A8: Cloudskraal | B8: Groenvlei | C8: C11 | D8: 2022 | E8: 41.979349 | F8: N.A | G8: N.A | H8: N.A | I8: N.A | J8: 15000 | K8: 20000 | L8: 25000 | M8: 10000 | N8: 5000 | O8: 0 | P8: 9000 | Q8: 15000 | R8: 30000 | S8: 20000 | T8: 0 | U8: 5000 | V8: 3000 | W8: 0 | X8: 0 | Y8: 0 | Z8: 16000 | AA8: 30000
A9: Cloudskraal | B9: Volkshuise | C9: C15 | D9: 2022 | E9: 7.293002 | F9: N.A | G9: N.A | H9: N.A | I9: N.A | J9: 0 | K9: 0 | L9: 0 | M9: 0 | N9: 0 | O9: 0 | P9: 0 | Q9: 0 | R9: 3500 | S9: 3500 | T9: 0 | U9: 2000 | V9: 0 | W9: 0 | X9: 0 | Y9: 0 | Z9: 2000 | AA9: 2000
A10: Cloudskraal | B10: Onderdam | C10: C17 | D10: 2022 | E10: 16.8566 | F10: N.A | G10: N.A | H10: N.A | I10: N.A | J10: 0 | K10: 0 | L10: 0 | M10: 0 | N10: 0 | O10: 0 | P10: 2000 | Q10: 6000 | R10: 11000 | S10: 7000 | T10: 0 | U10: 1000 | V10: 0 | W10: 12000 | X10: 0 | Y10: 0 | Z10: 7000 | AA10: 5000
A11: Cloudskraal | B11: Eerste Spilpunt | C11: C8 | D11: 2022 | E11: 21.626902 | F11: N.A | G11: N.A | H11: N.A | I11: N.A | J11: 8000 | K11: 0 | L11: 0 | M11: 0 | N11: 0 | O11: 0 | P11: 8000 | Q11: 8000 | R11: 4000 | S11: 0 | T11: 0 | U11: 6000 | V11: 15000 | W11: 15000 | X11: 0 | Y11: 0 | Z11: 8000 | AA11: 12000
A12: Glenridge | B12: Sandkamp | C12: G4 | D12: 2022 | E12: 52.153611 | F12: N.A | G12: N.A | H12: N.A | I12: N.A | J12: 5000 | K12: 0 | L12: 0 | M12: 25000 | N12: 20000 | O12: 15000 | P12: 10000 | Q12: 0 | R12: 0 | S12: 21000 | T12: 0 | U12: 6000 | V12: 2000 | W12: 8000 | X12: 0 | Y12: 0 | Z12: 31000 | AA12: 31000
A13: Glenridge | B13: Vleikamp B | C13: G8 | D13: 2022 | E13: 23.028313 | F13: N.A | G13: N.A | H13: N.A | I13: N.A | J13: 9000 | K13: 0 | L13: 0 | M13: 0 | N13: 0 | O13: 0 | P13: 0 | Q13: 0 | R13: 0 | S13: 4000 | T13: 0 | U13: 8000 | V13: 7000 | W13: 7000 | X13: 0 | Y13: 0 | Z13: 12000 | AA13: 10000
A14: Biekoes | B14: Tuinkamp | C14: B14 | D14: 2023 | E14: 8.6880705 | F14: N.A | G14: N.A | H14: N.A | I14: N.A | J14: 0 | K14: 0 | L14: 0 | M14: 0 | N14: 0 | O14: 0 | P14: 0 | Q14: 0 | R14: 0 | S14: 0 | T14: 0 | U14: 0 | V14: 0 | W14: 0 | X14: 0 | Y14: 0 | Z14: 0 | AA14: 2000
A15: Biekoes | B15: Bokant Dam | C15: B6 | D15: 2023 | E15: 42.898925 | F15: N.A | G15: N.A | H15: N.A | I15: N.A | J15: 0 | K15: 7000 | L15: 5000 | M15: 0 | N15: 0 | O15: 0 | P15: 0 | Q15: 0 | R15: 0 | S15: 25000 | T15: 0 | U15: 20000 | V15: 8000 | W15: 0 | X15: 0 | Y15: 0 | Z15: 0 | AA15: 12000
... A39: Glenridge | B39: Roosklawerkamp | C39: G6 | D39: 2027 | E39: 66.66814 | F39: N.A | G39: N.A | H39: N.A | I39: N.A | J39: 0 | K39: 0 | L39: 0 | M39: 0 | N39: 0 | O39: 10000 | P39: 15000 | Q39: 8000 | R39: 0 | S39: 0 | T39: 0 | U39: 0 | V39: 0 | W39: 10000 | X39: 20000 | Y39: 15000 | Z39: 12000 | AA39: 0
A40: Biekoes | B40: Donkiekamp | C40: B10 | D40: Braak | E40: 15.962332 | F40: N.A | G40: N.A | H40: N.A | I40: N.A | J40: 0 | K40: 0 | L40: 0 | M40: 0 | N40: 0 | O40: 0 | P40: 0 | Q40: 0 | R40: 0 | S40: 1000 | T40: 0 | U40: 2000 | V40: 0 | W40: 0 | X40: 0 | Y40: 0 | Z40: 0 | AA40: 0
A41: Biekoes | B41: Agter Huiskamp | C41: B11 | D41: Braak | E41: 15.497613 | F41: N.A | G41: N.A | H41: N.A | I41: N.A | J41: 0 | K41: 6000 | L41: 5000 | M41: 0 | N41: 0 | O41: 0 | P41: 0 | Q41: 0 | R41: 0 | S41: 8000 | T41: 0 | U41: 0 | V41: 0 | W41: 0 | X41: 0 | Y41: 0 | Z41: 0 | AA41: 0
A42: Biekoes | B42: Voor Huiskamp | C42: B13 | D42: Braak | E42: 27.417025 | F42: N.A | G42: N.A | H42: N.A | I42: N.A | J42: 0 | K42: 0 | L42: 0 | M42: 0 | N42: 0 | O42: 0 | P42: 0 | Q42: 0 | R42: 0 | S42: 2000 | T42: 0 | U42: 0 | V42: 0 | W42: 0 | X42: 0 | Y42: 0 | Z42: 0 | AA42: 0
A43: Cloudskraal | B43: By Begraafplaas | C43: C16 | D43: Braak | E43: 8.7379009 | F43: N.A | G43: N.A | H43: N.A | I43: N.A | J43: 0 | K43: 0 | L43: 0 | M43: 0 | N43: 0 | O43: 0 | P43: 0 | Q43: 0 | R43: 0 | S43: 0 | T43: 0 | U43: 1000 | V43: 0 | W43: 0 | X43: 0 | Y43: 0 | Z43: 0 | AA43: 0
A44: Glenridge | B44: Garskamp | C44: G10 | D44: Braak | E44: 10.953934 | F44: N.A | G44: N.A | H44: N.A | I44: N.A | J44: 1500 | K44: 0 | L44: 0 | M44: 0 | N44: 0 | O44: 2500 | P44: 2000 | Q44: 0 | R44: 0 | S44: 0 | T44: 0 | U44: 0 | V44: 0 | W44: 0 | X44: 0 | Y44: 0 | Z44: 0 | AA44: 0
A45: Glenridge | B45: Bokant Bloekoms | C45: G11 | D45: Braak | E45: 14.3042 | F45: N.A | G45: N.A | H45: N.A | I45: N.A | J45: 0 | K45: 0 | L45: 0 | M45: 0 | N45: 0 | O45: 6000 | P45: 4000 | Q45: 3000 | R45: 1500 | S45: 0 | T45: 0 | U45: 2000 | V45: 2000 | W45: 4000 | X45: 0 | Y45: 0 | Z45: 0 | AA45: 0
A46: Glenridge | B46: Klipland | C46: G12 | D46: Braak | E46: 4.6495434 | F46: N.A | G46: N.A | H46: N.A | I46: N.A | J46: 0 | K46: 0 | L46: 0 | M46: 0 | N46: 0 | O46: 2000 | P46: 0 | Q46: 0 | R46: 0 | S46: 0 | T46: 0 | U46: 0 | V46: 0 | W46: 0 | X46: 0 | Y46: 0 | Z46: 0 | AA46: 0
A47: Glenridge | B47: Teerpadland | C47: G7a | D47: Braak | E47: 7.6130991 | F47: N.A | G47: N.A | H47: N.A | I47: N.A | J47: 0 | K47: 0 | L47: 0 | M47: 0 | N47: 0 | O47: 1500 | P47: 10000 | Q47: 3000 | R47: 0 | S47: 3000 | T47: 1000 | U47: 1500 | V47: 0 | W47: 0 | X47: 0 | Y47: 0 | Z47: 0 | AA47: 0
A48: Glenridge | B48: Popelierland | C48: G7b | D48: Braak | E48: 1.2286475 | F48: N.A | G48: N.A | H48: N.A | I48: N.A | J48: 0 | K48: 0 | L48: 0 | M48: 0 | N48: 0 | O48: 1500 | P48: 10000 | Q48: 3000 | R48: 0 | S48: 1000 | T48: 500 | U48: 200 | V48: 0 | W48: 0 | X48: 0 | Y48: 0 | Z48: 0 | AA48: 0
A49: Glenridge | B49: Noordland | C49: G7c | D49: Braak | E49: 0.79330274 | F49: N.A | G49: N.A | H49: N.A | I49: N.A | J49: 0 | K49: 0 | L49: 0 | M49: 0 | N49: 0 | O49: 1500 | P49: 10000 | Q49: 3000 | R49: 0 | S49: 1000 | T49: 500 | U49: 500 | V49: 0 | W49: 0 | X49: 0 | Y49: 0 | Z49: 0 | AA49: 0
A50: Glenridge | B50: Plantjiesland | C50: G7d | D50: Braak | E50: 8.1720683 | F50: N.A | G50: N.A | H50: N.A | I50: N.A | J50: 0 | K50: 0 | L50: 0 | M50: 0 | N50: 0 | O50: 1500 | P50: 10000 | Q50: 3000 | R50: 0 | S50: 3000 | T50: 1000 | U50: 1000 | V50: 0 | W50: 0 | X50: 0 | Y50: 0 | Z50: 0 | AA50: 0
A51: Glenridge | B51: Deur-ry-land | C51: G7e | D51: Braak | E51: 3.2858996 | F51: N.A | G51: N.A | H51: N.A | I51: N.A | J51: 0 | K51: 0 | L51: 0 | M51: 0 | N51: 0 | O51: 1500 | P51: 10000 | Q51: 3000 | R51: 0 | S51: 0 | T51: 1000 | U51: 2000 | V51: 0 | W51: 0 | X51: 0 | Y51: 0 | Z51: 0 | AA51: 0
... A56: Garsland | B56: Stoorland | C56: GA6 | D56: Braak | E56: 3.0312657 | F56: N.A | G56: N.A | H56: N.A | I56: N.A | J56: 5000 | K56: 2000 | L56: 0 | M56: 0 | N56: 0 | O56: 0 | P56: 0 | Q56: 0 | R56: 0 | S56: 0 | T56: 0 | U56: 0 | V56: 0 | W56: 0 | X56: 0 | Y56: 0 | Z56: 0 | AA56: 0
D57: =SUM(Johan_Brand_Skatting_en_Werklik[GEPLANT]) -> 72868 | E57: =SUM(Johan_Brand_Skatting_en_Werklik[HEKTAAR]) -> 1049.3503 | I57: =SUM(Johan_Brand_Skatting_en_Werklik[2007_WERKLIK]) -> 0 | J57: =SUM(Johan_Brand_Skatting_en_Werklik[2008_WERKLIK]) -> 213000 | K57: =SUM(Johan_Brand_Skatting_en_Werklik[2009_WERKLIK]) -> 118000 | L57: =SUM(Johan_Brand_Skatting_en_Werklik[2010_WERKLIK]) -> 172000 | M57: =SUM(Johan_Brand_Skatting_en_Werklik[2011_WERKLIK]) -> 196000 | N57: =SUM(Johan_Brand_Skatting_en_Werklik[2012_WERKLIK]) -> 151000 | O57: =SUM(Johan_Brand_Skatting_en_Werklik[2013_WERKLIK]) -> 133500 | P57: =SUM(Johan_Brand_Skatting_en_Werklik[2014_WERKLIK]) -> 191500 | Q57: =SUM(Johan_Brand_Skatting_en_Werklik[2015_WERKLIK]) -> 124000 | R57: =SUM(Johan_Brand_Skatting_en_Werklik[2016_WERKLIK]) -> 203000 | S57: =SUM(Johan_Brand_Skatting_en_Werklik[2017_WERKLIK]) -> 321500 | T57: =SUM(Johan_Brand_Skatting_en_Werklik[2018_WERKLIK]) -> 17000 | U57: =SUM(Johan_Brand_Skatting_en_Werklik[2019_WERKLIK]) -> 194200 | V57: =SUM(Johan_Brand_Skatting_en_Werklik[2020_WERKLIK]) -> 158000 | W57: =SUM(Johan_Brand_Skatting_en_Werklik[2021_WERKLIK]) -> 193500 | X57: =SUM(Johan_Brand_Skatting_en_Werklik[2022_WERKLIK]) -> 110000 | Y57: =SUM(Johan_Brand_Skatting_en_Werklik[2023_WERKLIK]) -> 112000 | Z57: =SUM(Johan_Brand_Skatting_en_Werklik[2024_WERKLIK]) -> 190000 | AA57: =SUM(Johan_Brand_Skatting_en_Werklik[25_WERKLIK]) -> 244500
A59: PLAASNAAM | B59: LANDNAAM | C59: LANDNO | D59: GEPLANT | E59: HEKTAAR | F59: 2004 WERKLIK | G59: 2005 WERKLIK | H59: 2006_WERKLIK | I59: 2007_WERKLIK | J59: 2008_WERKLIK | K59: 2009_WERKLIK | L59: 2010_WERKLIK | M59: 2011_WERKLIK | N59: 2012_WERKLIK | O59: 2013_WERKLIK | P59: 2014_WERKLIK | Q59: 2015_WERKLIK | R59: 2016_WERKLIK | S59: 2017_WERKLIK | T59: 2018_WERKLIK | U59: 2019_WERKLIK | V59: 2020_WERKLIK | W59: 2021_WERKLIK | X59: 2022_WERKLIK | Y59: 2023_WERKLIK | Z59: 2024_WERKLIK | AA59: 25_WERKLIK
A60: Biekoes | B60: Spilpuntkamp | C60: B2 | D60: 2026 | E60: 18.110613 | F60: N.A | G60: N.A | H60: N.A | I60: N.A | J60: 0 | K60: 0 | L60: 331.29746 | M60: 220.86497 | N60: 0 | O60: 0 | P60: 0 | Q60: 0 | R60: 441.72994 | S60: 1380.4061 | T60: 0 | U60: 552.16243 | V60: 0 | W60: 0 | X60: 0 | Y60: 0 | Z60: 0 | AA60: 0
A61: Biekoes | B61: Eerste Land | C61: B1 | D61: 2022 | E61: 21.198753 | F61: N.A | G61: N.A | H61: N.A | I61: N.A | J61: 0 | K61: 0 | L61: 0 | M61: 377.38068 | N61: 0 | O61: 0 | P61: 0 | Q61: 0 | R61: 0 | S61: 754.76136 | T61: 0 | U61: 566.07102 | V61: 235.86293 | W61: 0 | X61: 0 | Y61: 0 | Z61: 283.03551 | AA61: 235.86293
A62: Biekoes | B62: Windpompkamp | C62: B4 | D62: 2026 | E62: 11.609562 | F62: N.A | G62: N.A | H62: N.A | I62: N.A | J62: 0 | K62: 86.135893 | L62: 0 | M62: 0 | N62: 0 | O62: 0 | P62: 0 | Q62: 0 | R62: 0 | S62: 258.40768 | T62: 0 | U62: 172.27179 | V62: 172.27179 | W62: 0 | X62: 0 | Y62: 0 | Z62: 86.135893 | AA62: 344.54357
A63: Cloudskraal | B63: Om Groenvlei | C63: C9 | D63: 2026 | E63: 29.471117 | F63: N.A | G63: N.A | H63: N.A | I63: N.A | J63: 848.28817 | K63: 237.52069 | L63: 0 | M63: 610.76748 | N63: 475.04137 | O63: 407.17832 | P63: 0 | Q63: 0 | R63: 1017.9458 | S63: 1017.9458 | T63: 0 | U63: 0 | V63: 0 | W63: 0 | X63: 0 | Y63: 305.38374 | Z63: 508.9729 | AA63: 508.9729
A64: Cloudskraal | B64: Groenvlei | C64: C11 | D64: 2022 | E64: 41.979349 | F64: N.A | G64: N.A | H64: N.A | I64: N.A | J64: 357.31855 | K64: 476.42473 | L64: 595.53091 | M64: 238.21237 | N64: 119.10618 | O64: 0 | P64: 214.39113 | Q64: 357.31855 | R64: 714.6371 | S64: 476.42473 | T64: 0 | U64: 119.10618 | V64: 71.46371 | W64: 0 | X64: 0 | Y64: 0 | Z64: 381.13979 | AA64: 714.6371
A65: Glenridge | B65: Driehoekkamp | C65: G1 | D65: 2026 | E65: 16.552962 | F65: N.A | G65: N.A | H65: N.A | I65: N.A | J65: 302.06075 | K65: 181.23645 | L65: 604.1215 | M65: 362.4729 | N65: 0 | O65: 0 | P65: 90.618225 | Q65: 302.06075 | R65: 302.06075 | S65: 604.1215 | T65: 0 | U65: 120.8243 | V65: 422.88505 | W65: 724.9458 | X65: 181.23645 | Y65: 0 | Z65: 0 | AA65: 0
A66: Glenridge | B66: Vleikamp B | C66: G8 | D66: 2022 | E66: 23.028313 | F66: N.A | G66: N.A | H66: N.A | I66: N.A | J66: 390.82324 | K66: 0 | L66: 0 | M66: 0 | N66: 0 | O66: 0 | P66: 0 | Q66: 0 | R66: 0 | S66: 173.69922 | T66: 0 | U66: 347.39844 | V66: 303.97363 | W66: 303.97363 | X66: 0 | Y66: 0 | Z66: 521.09765 | AA66: 434.24804
A67: Glenridge | B67: Baken se land | C67: G3 | D67: 2025 | E67: 53.627997 | F67: N.A | G67: N.A | H67: N.A | I67: N.A | J67: 186.46977 | K67: 55.94093 | L67: 0 | M67: 372.93953 | N67: 372.93953 | O67: 279.70465 | P67: 186.46977 | Q67: 0 | R67: 0 | S67: 149.17581 | T67: 0 | U67: 559.4093 | V67: 186.46977 | W67: 0 | X67: 372.93953 | Y67: 559.4093 | Z67: 484.82139 | AA67: 0
A68: Glenridge | B68: Sandkamp | C68: G4 | D68: 2022 | E68: 52.153611 | F68: N.A | G68: N.A | H68: N.A | I68: N.A | J68: 95.87064 | K68: 0 | L68: 0 | M68: 479.3532 | N68: 383.48256 | O68: 287.61192 | P68: 191.74128 | Q68: 0 | R68: 0 | S68: 402.65669 | T68: 0 | U68: 115.04477 | V68: 38.348256 | W68: 153.39302 | X68: 0 | Y68: 0 | Z68: 594.39797 | AA68: 594.39797
A69: Glenridge | B69: By Resovoir | C69: G14 | D69: 2026 | E69: 6.7325786 | F69: N.A | G69: N.A | H69: N.A | I69: N.A | J69: 0 | K69: 0 | L69: 0 | M69: 0 | N69: 0 | O69: 445.5945 | P69: 445.5945 | Q69: 148.5315 | R69: 0 | S69: 0 | T69: 0 | U69: 0 | V69: 148.5315 | W69: 445.5945 | X69: 0 | Y69: 0 | Z69: 0 | AA69: 519.86025
...

Sheet Rooibos - Johan Brand - Oeskatt
A1: PRODUKSIE DATA VAN CLOUDSKRAAL BOERDERY PER PLAAS, LAND EN GESKATTE OPBRENGS EN WERKLIKE OES IN KILOGRAMME.
F2: 2004
A3: PLAASNAAM | B3: LANDNAAM | C3: LANDNO | D3: GEPLANT | E3: HEKTAAR | F3: 2004 OESSKAT | G3: 2005 OESSKAT | H3: 2006 OESSKAT | I3: 2007_OESSKAT | J3: 2008_OESSKAT | K3: 2009_OESSKAT | L3: 2010_OESSKAT | M3: 2011_OESSKAT | N3: 2012_OESSKAT | O3: 2013_OESSKAT | P3: 2014_OESSKAT | Q3: 2015_OESSKAT | R3: 2016_OESSKAT | S3: 2017_OESSKAT | T3: 2018_OESSKAT | U3: 2019_OESSKAT | V3: 2020_OESSKAT | W3: 2021_OESSKAT | X3: 2022_OESSKAT | Y3: 2023_OESSKAT | Z3: 2024_OESSKAT | AA3: 2025_OESSKAT | AB3: 2026_OESSKAT | AC3: 2027_OESSKAT | AD3: 2028_OESSKAT
A4: Biekoes | B4: Spilpuntkamp | C4: B2 | D4: 2026 | E4: 18.110613 | F4: 0 | G4: 0 | H4: 15000 | I4: N.A | J4: 0 | K4: 0 | L4: 6000 | M4: 1000 | N4: 4000 | O4: 2000 | P4: 2000 | Q4: 2000 | R4: 4500 | S4: 34000 | T4: 9000 | U4: 10000 | V4: 0 | W4: 0 | X4: 15000 | Y4: 0 | Z4: 2000 | AA4: 0 | AB4: 0 | AC4: 2000 | AD4: 9000
A5: Biekoes | B5: Eerste Land | C5: B1 | D5: 2022 | E5: 21.198753 | F5: 0 | G5: 0 | H5: 0 | I5: N.A | J5: 0 | K5: 0 | L5: 0 | M5: 8000 | N5: 8000 | O5: 8000 | P5: 6000 | Q5: 0 | R5: 0 | S5: 16000 | T5: 16000 | U5: 12000 | V5: 5000 | W5: 0 | X5: 0 | Y5: 0 | Z5: 6000 | AA5: 4000 | AB5: 5000 | AC5: 0 | AD5: 0
A6: Biekoes | B6: Windpompkamp | C6: B4 | D6: 2026 | E6: 11.609562 | F6: 0 | G6: 0 | H6: 5000 | I6: N.A | J6: 3000 | K6: 2000 | L6: 0 | M6: 0 | N6: 0 | O6: 1000 | P6: 0 | Q6: 0 | R6: 0 | S6: 3000 | T6: 3000 | U6: 2000 | V6: 2000 | W6: 0 | X6: 1000 | Y6: 3000 | Z6: 1000 | AA6: 4000 | AB6: 0 | AC6: 1000 | AD6: 5000
A7: Cloudskraal | B7: Om Groenvlei | C7: C9 | D7: 2026 | E7: 29.471117 | F7: 0 | G7: 0 | H7: 25000 | I7: N.A | J7: 25000 | K7: 10000 | L7: 0 | M7: 18000 | N7: 18000 | O7: 12000 | P7: 0 | Q7: 3000 | R7: 12000 | S7: 30000 | T7: 8000 | U7: 0 | V7: 0 | W7: 3000 | X7: 3000 | Y7: 9000 | Z7: 15000 | AA7: 15000 | AB7: 0 | AC7: 0 | AD7: 0
A8: Cloudskraal | B8: Groenvlei | C8: C11 | D8: 2022 | E8: 41.979349 | F8: 24000 | G8: 15000 | H8: 15000 | I8: N.A | J8: 15000 | K8: 25000 | L8: 20000 | M8: 10000 | N8: 5000 | O8: 0 | P8: 0 | Q8: 30000 | R8: 15000 | S8: 20000 | T8: 10000 | U8: 5000 | V8: 5000 | W8: 3000 | X8: 0 | Y8: 0 | Z8: 16000 | AA8: 24000 | AB8: 20000 | AC8: 0 | AD8: 0
A9: Glenridge | B9: Driehoekkamp | C9: G1 | D9: 2026 | E9: 16.552962 | F9: 12000 | G9: 10000 | H9: 3000 | I9: N.A | J9: 5000 | K9: 5000 | L9: 3000 | M9: 6000 | N9: 0 | O9: 0 | P9: 0 | Q9: 8000 | R9: 5000 | S9: 12000 | T9: 5000 | U9: 2000 | V9: 7000 | W9: 12000 | X9: 5000 | Y9: 0 | Z9: 0 | AA9: 0 | AB9: 0 | AC9: 7000 | AD9: 0
